Workbook
Name Amount: #REF!
Name Amount: #REF!
Name Amount: #REF!
Name Amount: #REF!
Name Amount: #REF!
Name Amount: #REF!
Name Amount: #REF!
Name Date: #REF!
Name Date: #REF!
Name Date: #REF!
Name Date: #REF!
Name Date: #REF!
Name Date: #REF!
Name Date: #REF!
Name Description: #REF!
Name Description: #REF!
Name Description: #REF!
Name Description: #REF!
Name Description: #REF!
Name Description: #REF!
Name Description: #REF!
Name From: #REF!
Name From: #REF!
Name From: #REF!
Name From: #REF!
Name From: #REF!
Name From: #REF!
Name From: #REF!
Name To: #REF!
Name To: #REF!
Name To: #REF!
Name To: #REF!
Name To: #REF!
Name To: #REF!
Name To: #REF!

Sheet Report
F3: Sukuk Portfolio
C4: Platform | D4: Cost | E4: Total Suk. | F4: Completed | G4: Delayed | H4: Released Profit | I4: Expected Profit | J4: Cost+R Profit | K4: -1% Risk Factor | L4: Evaluated | M4: Return
C5: Sukuk Capital | D5: =Sukuk!A19 -> 0.7 | E5: =Sukuk!C23 -> 67 | F5: 1 | G5: 0 | H5: =Sukuk!B31 -> 29150.26 | I5: =Sukuk!B23-Sukuk!B31 -> 54992.42 | J5: =D5+H5 -> 29150.96 | K5: =J5/100 -> 291.5096 | L5: =J5-K5 -> 28859.45 | M5: =(L5-D5)/D5 -> 41226.786
C6: Dinar | D6: =#REF! -> #REF! | E6: =#REF! -> #REF! | F6: 0 | G6: 0 | H6: =#REF! -> #REF! | I6: =#REF!-#REF! -> #REF! | J6: =D6+H6 -> #REF! | K6: =J6/100 -> #REF! | L6: =J6-K6 -> #REF! | M6: =(L6-D6)/D6 -> #REF!
D7: =SUM(D5:D6) -> #REF! | E7: =SUM(E5:E6) -> #REF! | F7: =SUM(F5:F6) -> 1 | G7: =SUM(G5:G6) -> 0 | H7: =SUM(H5:H6) -> #REF! | I7: =SUM(I5:I6) -> #REF! | J7: =SUM(J5:J6) -> #REF! | K7: =SUM(K5:K6) -> #REF! | L7: =SUM(L5:L6) -> #REF! | M7: =(L7-D7)/D7 -> #REF!
F8: * | G8: *
B12: *Manwal

Sheet ALL
A1: أجمالي الأصول | B1: قيمة المحفظة | C1: الكاش | E1: المدة | F1: تاريخ الأستحقاق | G1: تاريخ السداد | H1: القيمة الأسمية | I1: صافي الربح | J1: الدفعة | K1: الحالة | L1: C | M1: A | N1: الشهر | O1: التدفقات | P1: رقم
A2: =SUM(B78:C78)+B2 -> 844787.09 | B2: =SUMIFS(J2:J326,F2:F326,"<>")+C2 -> 672337.44 | C2: =SUM(Sukuk!C1+Sukuk!C2+MANAFA!C2+LENDO!C2+TAMEED!C2+DINAR!C2+SAFQA!C2+TARMEEZ!C2) -> 34443.08 | E2: 16 | G2: 45484 | H2: 5000 | I2: 976.19 | J2: =SUM(H2:I2) -> 5976.19 | K2: PAID | N2: 45901 | O2: =SUMIFS(J$2:J$1009, F$2:F$1009, ">=" & DATE(YEAR(N2), MONTH(N2), 1), F$2:F$1009, "<=" & EOMONTH(N2, 0)) -> 0 | P2: 0
E3: 18 | G3: 45551 | H3: 5000 | I3: 1122.66 | J3: =SUM(H3:I3) -> 6122.66 | K3: PAID | N3: 45931 | O3: =SUMIFS(J$2:J$1009, F$2:F$1009, ">=" & DATE(YEAR(N3), MONTH(N3), 1), F$2:F$1009, "<=" & EOMONTH(N3, 0)) -> 5843.34 | P3: 0
E4: 20 | G4: 45575 | H4: 10000 | I4: 2378.56 | J4: =SUM(H4:I4) -> 12378.56 | K4: PAID | N4: 45962 | O4: =SUMIFS(J$2:J$1009, F$2:F$1009, ">=" & DATE(YEAR(N4), MONTH(N4), 1), F$2:F$1009, "<=" & EOMONTH(N4, 0)) -> 10280.28 | P4: 0
E5: 9 | G5: 45286 | H5: 5000 | I5: 459 | J5: =SUM(H5:I5) -> 5459 | K5: PAID | N5: 45992 | O5: =SUMIFS(J$2:J$1009, F$2:F$1009, ">=" & DATE(YEAR(N5), MONTH(N5), 1), F$2:F$1009, "<=" & EOMONTH(N5, 0)) -> 10729.61 | P5: 1
E6: 12 | G6: 45286 | H6: 5000 | I6: 607.05 | J6: =SUM(H6:I6) -> 5607.05 | K6: PAID | N6: 46023 | O6: =SUMIFS(J$2:J$1009, F$2:F$1009, ">=" & DATE(YEAR(N6), MONTH(N6), 1), F$2:F$1009, "<=" & EOMONTH(N6, 0)) -> 10463.54 | P6: 2
E7: 9 | G7: 45413 | H7: 20000 | I7: 1963.57 | J7: =SUM(H7:I7) -> 21963.57 | K7: PAID | L7: LATE | N7: 46054 | O7: =SUMIFS(J$2:J$1009, F$2:F$1009, ">=" & DATE(YEAR(N7), MONTH(N7), 1), F$2:F$1009, "<=" & EOMONTH(N7, 0)) -> 31643.95 | P7: 3
E8: 4 | G8: 45351 | H8: 20000 | I8: 826.52 | J8: =SUM(H8:I8) -> 20826.52 | K8: PAID | N8: 46082 | O8: =SUMIFS(J$2:J$1009, F$2:F$1009, ">=" & DATE(YEAR(N8), MONTH(N8), 1), F$2:F$1009, "<=" & EOMONTH(N8, 0)) -> 23128.39 | P8: 4
E9: 9 | G9: 45519 | H9: 10000 | I9: 953.2 | J9: =SUM(H9:I9) -> 10953.2 | K9: PAID | L9: LATE | N9: 46113 | O9: =SUMIFS(J$2:J$1009, F$2:F$1009, ">=" & DATE(YEAR(N9), MONTH(N9), 1), F$2:F$1009, "<=" & EOMONTH(N9, 0)) -> 29364.49 | P9: 5
E10: 17 | G10: 45742 | H10: 20000 | I10: 3744.86 | J10: =SUM(H10:I10) -> 23744.86 | K10: PAID | N10: 46143 | O10: =SUMIFS(J$2:J$1009, F$2:F$1009, ">=" & DATE(YEAR(N10), MONTH(N10), 1), F$2:F$1009, "<=" & EOMONTH(N10, 0)) -> 18578.03 | P10: 6
E11: 28 | F11: 46147 | H11: 5000 | I11: 1652.77 | J11: =SUM(H11:I11) -> 6652.77 | K11: =IF(F11<=TODAY(),"Check!","Waiting") -> Waiting | N11: 46174 | O11: =SUMIFS(J$2:J$1009, F$2:F$1009, ">=" & DATE(YEAR(N11), MONTH(N11), 1), F$2:F$1009, "<=" & EOMONTH(N11, 0)) -> 28338.37 | P11: 7
E12: 9 | G12: 45592 | H12: 5000 | I12: 463.86 | J12: =SUM(H12:I12) -> 5463.86 | K12: PAID | N12: 46204 | O12: =SUMIFS(J$2:J$1009, F$2:F$1009, ">=" & DATE(YEAR(N12), MONTH(N12), 1), F$2:F$1009, "<=" & EOMONTH(N12, 0)) -> 6485.95 | P12: 8
E13: 14 | G13: 45683 | H13: 5000 | I13: 631.95 | J13: =SUM(H13:I13) -> 5631.95 | K13: PAID | N13: 46235 | O13: =SUMIFS(J$2:J$1009, F$2:F$1009, ">=" & DATE(YEAR(N13), MONTH(N13), 1), F$2:F$1009, "<=" & EOMONTH(N13, 0)) -> 19687.91 | P13: 9
E14: 38 | F14: 46481 | H14: 5000 | I14: 2055.02 | J14: =SUM(H14:I14) -> 7055.02 | K14: =IF(F14<=TODAY(),"Check!","Waiting") -> Waiting | N14: 46266 | O14: =SUMIFS(J$2:J$1009, F$2:F$1009, ">=" & DATE(YEAR(N14), MONTH(N14), 1), F$2:F$1009, "<=" & EOMONTH(N14, 0)) -> 0 | P14: 10
E15: 24 | G15: 45452 | H15: 5000 | I15: 205.51 | J15: =SUM(H15:I15) -> 5205.51 | K15: PAID | N15: 46296 | O15: =SUMIFS(J$2:J$1009, F$2:F$1009, ">=" & DATE(YEAR(N15), MONTH(N15), 1), F$2:F$1009, "<=" & EOMONTH(N15, 0)) -> 24086 | P15: 11
E16: 16 | G16: 45812 | H16: 5000 | I16: 713.33 | J16: =SUM(H16:I16) -> 5713.33 | K16: PAID | L16: EARLY 7 | N16: 46327 | O16: =SUMIFS(J$2:J$1009, F$2:F$1009, ">=" & DATE(YEAR(N16), MONTH(N16), 1), F$2:F$1009, "<=" & EOMONTH(N16, 0)) -> 12083.62 | P16: 12
E17: 6 | G17: 45512 | H17: 10000 | I17: 569.01 | J17: =SUM(H17:I17) -> 10569.01 | K17: PAID | N17: 46357 | O17: =SUMIFS(J$2:J$1009, F$2:F$1009, ">=" & DATE(YEAR(N17), MONTH(N17), 1), F$2:F$1009, "<=" & EOMONTH(N17, 0)) -> 7297.5 | P17: 13
E18: 9 | G18: 45600 | H18: 5000 | I18: 390.38 | J18: =SUM(H18:I18) -> 5390.38 | K18: PAID | N18: 46388 | O18: =SUMIFS(J$2:J$1009, F$2:F$1009, ">=" & DATE(YEAR(N18), MONTH(N18), 1), F$2:F$1009, "<=" & EOMONTH(N18, 0)) -> 6547.1 | P18: 14
E19: 10 | G19: 45669 | H19: 5000 | I19: 428.76 | J19: =SUM(H19:I19) -> 5428.76 | K19: PAID | N19: 46419 | O19: =SUMIFS(J$2:J$1009, F$2:F$1009, ">=" & DATE(YEAR(N19), MONTH(N19), 1), F$2:F$1009, "<=" & EOMONTH(N19, 0)) -> 24220 | P19: 15
E20: 6 | G20: 45561 | H20: 5000 | I20: 300.25 | J20: =SUM(H20:I20) -> 5300.25 | K20: PAID | N20: 46447 | O20: =SUMIFS(J$2:J$1009, F$2:F$1009, ">=" & DATE(YEAR(N20), MONTH(N20), 1), F$2:F$1009, "<=" & EOMONTH(N20, 0)) -> 37672.51 | P20: 16
E21: 9 | G21: 45655 | H21: 5000 | I21: 458.24 | J21: =SUM(H21:I21) -> 5458.24 | K21: PAID | N21: 46478 | O21: =SUMIFS(J$2:J$1009, F$2:F$1009, ">=" & DATE(YEAR(N21), MONTH(N21), 1), F$2:F$1009, "<=" & EOMONTH(N21, 0)) -> 7055.02 | P21: 17
E22: 6 | G22: 45565 | H22: 5000 | I22: 280 | J22: =SUM(H22:I22) -> 5280 | K22: PAID | N22: 46508 | O22: =SUMIFS(J$2:J$1009, F$2:F$1009, ">=" & DATE(YEAR(N22), MONTH(N22), 1), F$2:F$1009, "<=" & EOMONTH(N22, 0)) -> 18844.23 | P22: 18
E23: 9 | G23: 45649 | H23: 5000 | I23: 431.37 | J23: =SUM(H23:I23) -> 5431.37 | K23: PAID | N23: 46539 | O23: =SUMIFS(J$2:J$1009, F$2:F$1009, ">=" & DATE(YEAR(N23), MONTH(N23), 1), F$2:F$1009, "<=" & EOMONTH(N23, 0)) -> 10287 | P23: 19
E24: 13 | F24: 45792 | H24: 5000 | I24: 610.29 | J24: =SUM(H24:I24) -> 5610.29 | K24: =IF(F24<=TODAY(),"Check!","Waiting") -> Check! | L24: DEF | N24: 46569 | O24: =SUMIFS(J$2:J$1009, F$2:F$1009, ">=" & DATE(YEAR(N24), MONTH(N24), 1), F$2:F$1009, "<=" & EOMONTH(N24, 0)) -> 42606.08 | P24: 20
E25: 24 | G25: 45705 | H25: 5000 | I25: 481.39 | J25: =SUM(H25:I25) -> 5481.39 | K25: PAID | N25: 46600 | O25: =SUMIFS(J$2:J$1009, F$2:F$1009, ">=" & DATE(YEAR(N25), MONTH(N25), 1), F$2:F$1009, "<=" & EOMONTH(N25, 0)) -> 36468 | P25: 21
E26: 24 | F26: 46140 | H26: 5000 | I26: 1151.34 | J26: =SUM(H26:I26) -> 6151.34 | K26: =IF(F26<=TODAY(),"Check!","Waiting") -> Waiting | N26: 46631 | O26: =SUMIFS(J$2:J$1009, F$2:F$1009, ">=" & DATE(YEAR(N26), MONTH(N26), 1), F$2:F$1009, "<=" & EOMONTH(N26, 0)) -> 13216.12 | P26: 22
E27: 17 | G27: 45922 | H27: 5000 | I27: 936.94 | J27: =SUM(H27:I27) -> 5936.94 | K27: PAID | M27: SU1 | N27: 46661 | O27: =SUMIFS(J$2:J$1009, F$2:F$1009, ">=" & DATE(YEAR(N27), MONTH(N27), 1), F$2:F$1009, "<=" & EOMONTH(N27, 0)) -> 0 | P27: 23
E28: 17 | F28: 45931 | H28: 5000 | I28: 843.34 | J28: =SUM(H28:I28) -> 5843.34 | K28: PAID | M28: SU1 | N28: 46692 | O28: =SUMIFS(J$2:J$1009, F$2:F$1009, ">=" & DATE(YEAR(N28), MONTH(N28), 1), F$2:F$1009, "<=" & EOMONTH(N28, 0)) -> 39303.83 | P28: 24
E29: 13 | G29: 45811 | H29: 5000 | I29: 622.41 | J29: =SUM(H29:I29) -> 5622.41 | K29: PAID | L29: EARLY 12 | N29: 46722 | O29: =SUMIFS(J$2:J$1009, F$2:F$1009, ">=" & DATE(YEAR(N29), MONTH(N29), 1), F$2:F$1009, "<=" & EOMONTH(N29, 0)) -> 39263.23 | P29: 25
A30: Note | E30: 24 | F30: 46145 | H30: 5000 | I30: 1251.93 | J30: =SUM(H30:I30) -> 6251.93 | K30: =IF(F30<=TODAY(),"Check!","Waiting") -> Waiting | N30: 46753 | O30: =SUMIFS(J$2:J$1009, F$2:F$1009, ">=" & DATE(YEAR(N30), MONTH(N30), 1), F$2:F$1009, "<=" & EOMONTH(N30, 0)) -> 0 | P30: 26
A31: Cash sum and subtract until cell 300. update if needed | E31: 9 | G31: 45753 | H31: 5000 | I31: 341.49 | J31: =SUM(H31:I31) -> 5341.49 | K31: PAID | N31: 46784 | O31: =SUMIFS(J$2:J$1009, F$2:F$1009, ">=" & DATE(YEAR(N31), MONTH(N31), 1), F$2:F$1009, "<=" & EOMONTH(N31, 0)) -> 13760.06 | P31: 27
E32: 18 | F32: 46196 | H32: 20000 | I32: 2154.87 | J32: =SUM(H32:I32) -> 22154.87 | K32: =IF(F32<=TODAY(),"Check!","Waiting") -> Waiting | N32: 46813 | O32: =SUMIFS(J$2:J$1009, F$2:F$1009, ">=" & DATE(YEAR(N32), MONTH(N32), 1), F$2:F$1009, "<=" & EOMONTH(N32, 0)) -> 34726.23 | P32: 28
E33: 30 | F33: 46110 | H33: 8000 | I33: 2571.94 | J33: =SUM(H33:I33) -> 10571.94 | K33: =IF(F33<=TODAY(),"Check!","Waiting") -> Waiting | N33: 46844 | O33: =SUMIFS(J$2:J$1009, F$2:F$1009, ">=" & DATE(YEAR(N33), MONTH(N33), 1), F$2:F$1009, "<=" & EOMONTH(N33, 0)) -> 0 | P33: 29
E34: 12 | F34: 46021 | H34: 4000 | I34: 396.34 | J34: =SUM(H34:I34) -> 4396.34 | K34: =IF(F34<=TODAY(),"Check!","Waiting") -> Waiting | N34: 46874 | O34: =SUMIFS(J$2:J$1009, F$2:F$1009, ">=" & DATE(YEAR(N34), MONTH(N34), 1), F$2:F$1009, "<=" & EOMONTH(N34, 0)) -> 7441.19 | P34: 30
E35: 9 | G35: 45901 | H35: 5000 | I35: 532.94 | J35: =SUM(H35:I35) -> 5532.94 | K35: PAID | L35: EARLY 30 | M35: SA | N35: 46905 | O35: =SUMIFS(J$2:J$1009, F$2:F$1009, ">=" & DATE(YEAR(N35), MONTH(N35), 1), F$2:F$1009, "<=" & EOMONTH(N35, 0)) -> 0 | P35: 31
E36: 26 | F36: 46453 | H36: 5000 | I36: 1518.87 | J36: =SUM(H36:I36) -> 6518.87 | K36: =IF(F36<=TODAY(),"Check!","Waiting") -> Waiting | N36: 46935 | O36: =SUMIFS(J$2:J$1009, F$2:F$1009, ">=" & DATE(YEAR(N36), MONTH(N36), 1), F$2:F$1009, "<=" & EOMONTH(N36, 0)) -> 0 | P36: 32
E37: 23 | F37: 46448 | H37: 10000 | I37: 2583.52 | J37: =SUM(H37:I37) -> 12583.52 | K37: =IF(F37<=TODAY(),"Check!","Waiting") -> Waiting | N37: 46966 | O37: =SUMIFS(J$2:J$1009, F$2:F$1009, ">=" & DATE(YEAR(N37), MONTH(N37), 1), F$2:F$1009, "<=" & EOMONTH(N37, 0)) -> 0 | P37: 33
E38: 13 | F38: 46145 | H38: 5000 | I38: 673.33 | J38: =SUM(H38:I38) -> 5673.33 | K38: =IF(F38<=TODAY(),"Check!","Waiting") -> Waiting | N38: 46997 | O38: =SUMIFS(J$2:J$1009, F$2:F$1009, ">=" & DATE(YEAR(N38), MONTH(N38), 1), F$2:F$1009, "<=" & EOMONTH(N38, 0)) -> 27780 | P38: 34
E39: 27 | F39: 46575 | H39: 10000 | I39: 2885.89 | J39: =SUM(H39:I39) -> 12885.89 | K39: =IF(F39<=TODAY(),"Check!","Waiting") -> Waiting | N39: 47027 | O39: =SUMIFS(J$2:J$1009, F$2:F$1009, ">=" & DATE(YEAR(N39), MONTH(N39), 1), F$2:F$1009, "<=" & EOMONTH(N39, 0)) -> 0 | P39: 35
E40: 19 | F40: 46348 | H40: 10000 | I40: 2083.62 | J40: =SUM(H40:I40) -> 12083.62 | K40: =IF(F40<=TODAY(),"Check!","Waiting") -> Waiting | N40: 47058 | O40: =SUMIFS(J$2:J$1009, F$2:F$1009, ">=" & DATE(YEAR(N40), MONTH(N40), 1), F$2:F$1009, "<=" & EOMONTH(N40, 0)) -> 0
...

Sheet Sukuk
A1: قيمة المحفظة | C1: 31586.18 | E1: المدة | F1: تاريخ الأستحقاق | G1: تاريخ السداد | H1: القيمة الأسمية | I1: صافي الربح | J1: الدفعة | K1: الحالة | L1: C | M1: أسم الصك | N1: النسبة السنوية | P1: الشهر | Q1: التدفقات | R1: CHECKLIST
A2: =SUMIFS(J2:J300,F2:F300,"<>")+B19+A19+C1+C2 -> 400586.87 | C2: 2856.9 | E2: 16 | G2: 45484 | H2: 5000 | I2: 976.19 | J2: =SUM(H2:I2) -> 5976.19 | K2: PAID | M2: 001-02623 2# | N2: 16 | P2: 45778 | Q2: =SUMIFS(J$2:J$1000, F$2:F$1000, ">=" & DATE(YEAR(P2), MONTH(P2), 1), F$2:F$1000, "<=" & EOMONTH(P2, 0)) -> 5610.29
E3: 18 | G3: 45551 | H3: 5000 | I3: 1122.66 | J3: =SUM(H3:I3) -> 6122.66 | K3: PAID | M3: 001-02623 4# | N3: 16.2 | P3: 45809 | Q3: =SUMIFS(J$2:J$1000, F$2:F$1000, ">=" & DATE(YEAR(P3), MONTH(P3), 1), F$2:F$1000, "<=" & EOMONTH(P3, 0)) -> 0 | R3: بداية الأستثمار
A4: الملاحظات | E4: 20 | G4: 45575 | H4: 10000 | I4: 2378.56 | J4: =SUM(H4:I4) -> 12378.56 | K4: PAID | M4: 001-02623 5# | N4: 16.4 | P4: 45839 | Q4: =SUMIFS(J$2:J$1000, F$2:F$1000, ">=" & DATE(YEAR(P4), MONTH(P4), 1), F$2:F$1000, "<=" & EOMONTH(P4, 0)) -> 0 | R4: اضف معلومات الاستثمار
E5: 9 | G5: 45286 | H5: 5000 | I5: 459 | J5: =SUM(H5:I5) -> 5459 | K5: PAID | M5: 001-4059 | N5: 13.5 | P5: 45870 | Q5: =SUMIFS(J$2:J$1000, F$2:F$1000, ">=" & DATE(YEAR(P5), MONTH(P5), 1), F$2:F$1000, "<=" & EOMONTH(P5, 0)) -> 0 | R5: اخصم المبلغ من الكاش
A6: الفرص ذات التوزيعات 28 | E6: 12 | G6: 45286 | H6: 5000 | I6: 607.05 | J6: =SUM(H6:I6) -> 5607.05 | K6: PAID | M6: 001-2834 | N6: 13.3 | P6: 45901 | Q6: =SUMIFS(J$2:J$1000, F$2:F$1000, ">=" & DATE(YEAR(P6), MONTH(P6), 1), F$2:F$1000, "<=" & EOMONTH(P6, 0)) -> 0 | R6: انسخة كاملة السطر الى ALL
E7: 9 | G7: 45413 | H7: 20000 | I7: 1963.57 | J7: =SUM(H7:I7) -> 21963.57 | K7: PAID | L7: LATE | M7: 001-3926 | N7: 14.2 | P7: 45931 | Q7: =SUMIFS(J$2:J$1000, F$2:F$1000, ">=" & DATE(YEAR(P7), MONTH(P7), 1), F$2:F$1000, "<=" & EOMONTH(P7, 0)) -> 0 | R7: تحقق من التدفقات
E8: 4 | G8: 45351 | H8: 20000 | I8: 826.52 | J8: =SUM(H8:I8) -> 20826.52 | K8: PAID | M8: 001-4381 | N8: 14.2 | P8: 45962 | Q8: =SUMIFS(J$2:J$1000, F$2:F$1000, ">=" & DATE(YEAR(P8), MONTH(P8), 1), F$2:F$1000, "<=" & EOMONTH(P8, 0)) -> 0
E9: 9 | G9: 45519 | H9: 10000 | I9: 953.2 | J9: =SUM(H9:I9) -> 10953.2 | K9: PAID | L9: LATE | M9: 001-7936 | N9: 13.9 | P9: 45992 | Q9: =SUMIFS(J$2:J$1000, F$2:F$1000, ">=" & DATE(YEAR(P9), MONTH(P9), 1), F$2:F$1000, "<=" & EOMONTH(P9, 0)) -> 10729.61
A10: جميع الأرقام تم التأكد منها | E10: 17 | G10: 45742 | H10: 20000 | I10: 3744.86 | J10: =SUM(H10:I10) -> 23744.86 | K10: PAID | M10: 002-0535 | N10: 14.8 | P10: 46023 | Q10: =SUMIFS(J$2:J$1000, F$2:F$1000, ">=" & DATE(YEAR(P10), MONTH(P10), 1), F$2:F$1000, "<=" & EOMONTH(P10, 0)) -> 0 | R10: نهاية الأستثمار
A11: جميع التأخر والتعثر تم التأكد منها | E11: 28 | F11: 46147 | H11: 5000 | I11: 1652.77 | J11: =SUM(H11:I11) -> 6652.77 | K11: =IF(F11<=TODAY(),"Check!","Waiting") -> Waiting | M11: 001-08010 | N11: 15.2 | P11: 46054 | Q11: =SUMIFS(J$2:J$1000, F$2:F$1000, ">=" & DATE(YEAR(P11), MONTH(P11), 1), F$2:F$1000, "<=" & EOMONTH(P11, 0)) -> 0 | R11: PAID
A12: مطلوب : التأكد من جميع السداد المبكر | E12: 9 | G12: 45592 | H12: 5000 | I12: 463.86 | J12: =SUM(H12:I12) -> 5463.86 | K12: PAID | M12: 001-09127 | N12: 13.5 | P12: 46082 | Q12: =SUMIFS(J$2:J$1000, F$2:F$1000, ">=" & DATE(YEAR(P12), MONTH(P12), 1), F$2:F$1000, "<=" & EOMONTH(P12, 0)) -> 17190.89 | R12: غير مكان تاريخ الاستحقاق الى تاريخ السداد
E13: 14 | G13: 45683 | H13: 5000 | I13: 631.95 | J13: =SUM(H13:I13) -> 5631.95 | K13: PAID | M13: 001-7215 | N13: 13.8 | P13: 46113 | Q13: =SUMIFS(J$2:J$1000, F$2:F$1000, ">=" & DATE(YEAR(P13), MONTH(P13), 1), F$2:F$1000, "<=" & EOMONTH(P13, 0)) -> 29364.49 | R13: غير صافي الربح
E14: 38 | F14: 46481 | H14: 5000 | I14: 2055.02 | J14: =SUM(H14:I14) -> 7055.02 | K14: =IF(F14<=TODAY(),"Check!","Waiting") -> Waiting | M14: 001-1101 | N14: 14.1 | P14: 46143 | Q14: =SUMIFS(J$2:J$1000, F$2:F$1000, ">=" & DATE(YEAR(P14), MONTH(P14), 1), F$2:F$1000, "<=" & EOMONTH(P14, 0)) -> 18578.03 | R14: اكتب / EARLY OR LATE OR DEF
E15: 24 | G15: 45452 | H15: 5000 | I15: 205.51 | J15: =SUM(H15:I15) -> 5205.51 | K15: PAID | M15: النايفية العقارية | N15: 13.1 | P15: 46174 | Q15: =SUMIFS(J$2:J$1000, F$2:F$1000, ">=" & DATE(YEAR(P15), MONTH(P15), 1), F$2:F$1000, "<=" & EOMONTH(P15, 0)) -> 22154.87 | R15: اضف مبلغ الدفعة الى الكاش
E16: 16 | G16: 45812 | H16: 5000 | I16: 713.33 | J16: =SUM(H16:I16) -> 5713.33 | K16: PAID | L16: EARLY 7 | M16: 001-0523 | N16: 11.8 | P16: 46204 | Q16: =SUMIFS(J$2:J$1000, F$2:F$1000, ">=" & DATE(YEAR(P16), MONTH(P16), 1), F$2:F$1000, "<=" & EOMONTH(P16, 0)) -> 6485.95 | R16: انسخ كامل السطر الى ALL
E17: 6 | G17: 45512 | H17: 10000 | I17: 569.01 | J17: =SUM(H17:I17) -> 10569.01 | K17: PAID | M17: 001-5171 | N17: 13.2 | P17: 46235 | Q17: =SUMIFS(J$2:J$1000, F$2:F$1000, ">=" & DATE(YEAR(P17), MONTH(P17), 1), F$2:F$1000, "<=" & EOMONTH(P17, 0)) -> 19687.91
A18: تم التأكد من جمييييع الأرقام مع قيمة المحفظة ك كل 700,948 | E18: 9 | G18: 45600 | H18: 5000 | I18: 390.38 | J18: =SUM(H18:I18) -> 5390.38 | K18: PAID | M18: 001-5243 | N18: 12.3 | P18: 46266 | Q18: =SUMIFS(J$2:J$1000, F$2:F$1000, ">=" & DATE(YEAR(P18), MONTH(P18), 1), F$2:F$1000, "<=" & EOMONTH(P18, 0)) -> 0
A19: 0.7 | B19: 0.41 | C19: تصحيح الفواصل | E19: 10 | G19: 45669 | H19: 5000 | I19: 428.76 | J19: =SUM(H19:I19) -> 5428.76 | K19: PAID | M19: تالة العقارية | N19: 11.4 | P19: 46296 | Q19: =SUMIFS(J$2:J$1000, F$2:F$1000, ">=" & DATE(YEAR(P19), MONTH(P19), 1), F$2:F$1000, "<=" & EOMONTH(P19, 0)) -> 0
E20: 6 | G20: 45561 | H20: 5000 | I20: 300.25 | J20: =SUM(H20:I20) -> 5300.25 | K20: PAID | M20: 001-101472 1# | N20: 13.2 | P20: 46327 | Q20: =SUMIFS(J$2:J$1000, F$2:F$1000, ">=" & DATE(YEAR(P20), MONTH(P20), 1), F$2:F$1000, "<=" & EOMONTH(P20, 0)) -> 12083.62
A21: المأشرات | E21: 9 | G21: 45655 | H21: 5000 | I21: 458.24 | J21: =SUM(H21:I21) -> 5458.24 | K21: PAID | M21: 001-101472 2# | N21: 13.4 | P21: 46357 | Q21: =SUMIFS(J$2:J$1000, F$2:F$1000, ">=" & DATE(YEAR(P21), MONTH(P21), 1), F$2:F$1000, "<=" & EOMONTH(P21, 0)) -> 0
A22: القيمة الأسمية | B22: صافي الأرباح | C22: عدد الأستثمارات | E22: 6 | G22: 45565 | H22: 5000 | I22: 280 | J22: =SUM(H22:I22) -> 5280 | K22: PAID | M22: 001-010589 1# | N22: 12.3 | P22: 46388 | Q22: =SUMIFS(J$2:J$1000, F$2:F$1000, ">=" & DATE(YEAR(P22), MONTH(P22), 1), F$2:F$1000, "<=" & EOMONTH(P22, 0)) -> 6547.1
A23: =SUMIFS(H2:H300,F2:F300,"<>") -> 282000 | B23: =SUMIFS(I2:I300,F2:F300,"<>") -> 84142.68 | C23: =COUNT(N2:N300, "?*") -> 67 | E23: 9 | G23: 45649 | H23: 5000 | I23: 431.37 | J23: =SUM(H23:I23) -> 5431.37 | K23: PAID | M23: 001-10536 | N23: 13 | P23: 46419 | Q23: =SUMIFS(J$2:J$1000, F$2:F$1000, ">=" & DATE(YEAR(P23), MONTH(P23), 1), F$2:F$1000, "<=" & EOMONTH(P23, 0)) -> 0
A24: العائد السنوي ( APR ) | B24: العائد على الاستثمار ( ROI ) | C24: متوسط المدة ( بالشهر ) | E24: 13 | F24: 45792 | H24: 5000 | I24: 610.29 | J24: =SUM(H24:I24) -> 5610.29 | K24: =IF(F24<=TODAY(),"Check!","Waiting") -> Check! | L24: LATE | M24: 003-0728 | N24: 14.7 | P24: 46447 | Q24: =SUMIFS(J$2:J$1000, F$2:F$1000, ">=" & DATE(YEAR(P24), MONTH(P24), 1), F$2:F$1000, "<=" & EOMONTH(P24, 0)) -> 25596.38
A25: =AVERAGE(N2:N500) -> 14.016567 | B25: =TEXT(B23/A23, "0.00%") -> 29.84% | C25: =SUMPRODUCT(H2:H500, E2:E500) / SUM(H2:H500) -> 10.611111 | E25: 24 | G25: 45705 | H25: 5000 | I25: 481.39 | J25: =SUM(H25:I25) -> 5481.39 | K25: PAID | M25: النايفية ريزدنس 10 | N25: 12.9 | P25: 46478 | Q25: =SUMIFS(J$2:J$1000, F$2:F$1000, ">=" & DATE(YEAR(P25), MONTH(P25), 1), F$2:F$1000, "<=" & EOMONTH(P25, 0)) -> 7055.02
A26: الفرص المتأخرة | B26: الفرص النشطة | C26: الفرص المكتملة | E26: 24 | F26: 46140 | H26: 5000 | I26: 1151.34 | J26: =SUM(H26:I26) -> 6151.34 | K26: =IF(F26<=TODAY(),"Check!","Waiting") -> Waiting | M26: الرضا السكني | N26: 12.7 | P26: 46508 | Q26: =SUMIFS(J$2:J$1000, F$2:F$1000, ">=" & DATE(YEAR(P26), MONTH(P26), 1), F$2:F$1000, "<=" & EOMONTH(P26, 0)) -> 6429.23
A27: =COUNTIF(K2:K300, "CHECK!") -> 1 | B27: =COUNTIF(K2:K300, "WAITING") -> 31 | C27: =COUNTIF(K2:K300, "PAID") -> 35 | E27: 17 | G27: 45922 | H27: 5000 | I27: 936.94 | J27: =SUM(H27:I27) -> 5936.94 | K27: PAID | M27: 003-350 | N27: 14.4 | P27: 46539 | Q27: =SUMIFS(J$2:J$1000, F$2:F$1000, ">=" & DATE(YEAR(P27), MONTH(P27), 1), F$2:F$1000, "<=" & EOMONTH(P27, 0)) -> 0
E28: 17 | G28: 45931 | H28: 5000 | I28: 843.34 | J28: =SUM(H28:I28) -> 5843.34 | K28: PAID | M28: 001-010589 | N28: 13.1 | P28: 46569 | Q28: =SUMIFS(J$2:J$1000, F$2:F$1000, ">=" & DATE(YEAR(P28), MONTH(P28), 1), F$2:F$1000, "<=" & EOMONTH(P28, 0)) -> 42606.08
E29: 13 | G29: 45811 | H29: 5000 | I29: 622.41 | J29: =SUM(H29:I29) -> 5622.41 | K29: PAID | L29: EARLY 12 | M29: 002-01207 | N29: 12.4 | P29: 46600 | Q29: =SUMIFS(J$2:J$1000, F$2:F$1000, ">=" & DATE(YEAR(P29), MONTH(P29), 1), F$2:F$1000, "<=" & EOMONTH(P29, 0)) -> 0
A30: القيمة الأسمية المدفوعة | B30: صافي الأرباح المدفوع | C30: المجموع | E30: 24 | F30: 46145 | H30: 5000 | I30: 1251.93 | J30: =SUM(H30:I30) -> 6251.93 | K30: =IF(F30<=TODAY(),"Check!","Waiting") -> Waiting | M30: بيان 3 | N30: 13.7 | P30: 46631 | Q30: =SUMIFS(J$2:J$1000, F$2:F$1000, ">=" & DATE(YEAR(P30), MONTH(P30), 1), F$2:F$1000, "<=" & EOMONTH(P30, 0)) -> 13216.12
A31: =SUMIFS(H2:H167,G2:G167,"<>") -> 240000 | B31: =SUMIFS(I2:I167,G2:G167,"<>") -> 29150.26 | C31: =A31+B31 -> 269150.26 | E31: 9 | G31: 45753 | H31: 5000 | I31: 341.49 | J31: =SUM(H31:I31) -> 5341.49 | K31: PAID | M31: 001-6495 | N31: 14.6 | P31: 46661 | Q31: =SUMIFS(J$2:J$1000, F$2:F$1000, ">=" & DATE(YEAR(P31), MONTH(P31), 1), F$2:F$1000, "<=" & EOMONTH(P31, 0)) -> 0
A32: المجموع | E32: 18 | F32: 46196 | H32: 20000 | I32: 2154.87 | J32: =SUM(H32:I32) -> 22154.87 | K32: =IF(F32<=TODAY(),"Check!","Waiting") -> Waiting | M32: محمد بانعبم للتجارة | N32: 14.3 | P32: 46692 | Q32: =SUMIFS(J$2:J$1000, F$2:F$1000, ">=" & DATE(YEAR(P32), MONTH(P32), 1), F$2:F$1000, "<=" & EOMONTH(P32, 0)) -> 26053.94
A33: HOW TO USE: | E33: 30 | F33: 46110 | H33: 8000 | I33: 2571.94 | J33: =SUM(H33:I33) -> 10571.94 | K33: =IF(F33<=TODAY(),"Check!","Waiting") -> Waiting | M33: 001-11286 | N33: 14 | P33: 46722 | Q33: =SUMIFS(J$2:J$1000, F$2:F$1000, ">=" & DATE(YEAR(P33), MONTH(P33), 1), F$2:F$1000, "<=" & EOMONTH(P33, 0)) -> 13045.67
A34: In the Due culum, when the date come it will change to red | E34: 12 | F34: 46021 | H34: 4000 | I34: 396.34 | J34: =SUM(H34:I34) -> 4396.34 | K34: =IF(F34<=TODAY(),"Check!","Waiting") -> Waiting | M34: 001-12791 | N34: 11.1 | P34: 46753 | Q34: =SUMIFS(J$2:J$1000, F$2:F$1000, ">=" & DATE(YEAR(P34), MONTH(P34), 1), F$2:F$1000, "<=" & EOMONTH(P34, 0)) -> 0
A35: if its PAID, then type the Paiment date = this will compute the profits | E35: 9 | G35: 45901 | H35: 5000 | I35: 532.94 | J35: =SUM(H35:I35) -> 5532.94 | K35: PAID | L35: ERLY 30 / بيع ارض | M35: 001-14552 | N35: 18.3 | P35: 46784 | Q35: =SUMIFS(J$2:J$1000, F$2:F$1000, ">=" & DATE(YEAR(P35), MONTH(P35), 1), F$2:F$1000, "<=" & EOMONTH(P35, 0)) -> 13760.06
A36: automatically in the portfolio value | E36: 26 | F36: 46453 | H36: 5000 | I36: 1518.87 | J36: =SUM(H36:I36) -> 6518.87 | K36: =IF(F36<=TODAY(),"Check!","Waiting") -> Waiting | M36: يامن للتطوير العقاري | N36: 15.2 | P36: 46813 | Q36: =SUMIFS(J$2:J$1000, F$2:F$1000, ">=" & DATE(YEAR(P36), MONTH(P36), 1), F$2:F$1000, "<=" & EOMONTH(P36, 0)) -> 34726.23
A37: then type (PAID) to change to green | E37: 23 | F37: 46448 | H37: 10000 | I37: 2583.52 | J37: =SUM(H37:I37) -> 12583.52 | K37: =IF(F37<=TODAY(),"Check!","Waiting") -> Waiting | M37: الراسيات ريزدينس 27# | N37: 14.6 | P37: 46844 | Q37: =SUMIFS(J$2:J$1000, F$2:F$1000, ">=" & DATE(YEAR(P37), MONTH(P37), 1), F$2:F$1000, "<=" & EOMONTH(P37, 0)) -> 0
E38: 13 | F38: 46145 | H38: 5000 | I38: 673.33 | J38: =SUM(H38:I38) -> 5673.33 | K38: =IF(F38<=TODAY(),"Check!","Waiting") -> Waiting | M38: الدرر للمقاولات | N38: 13.6 | P38: 46874 | Q38: =SUMIFS(J$2:J$1000, F$2:F$1000, ">=" & DATE(YEAR(P38), MONTH(P38), 1), F$2:F$1000, "<=" & EOMONTH(P38, 0)) -> 7441.19
A39: Note | E39: 27 | F39: 46575 | H39: 10000 | I39: 2885.89 | J39: =SUM(H39:I39) -> 12885.89 | K39: =IF(F39<=TODAY(),"Check!","Waiting") -> Waiting | M39: بدء 41 | N39: 14 | P39: 46905 | Q39: =SUMIFS(J$2:J$1000, F$2:F$1000, ">=" & DATE(YEAR(P39), MONTH(P39), 1), F$2:F$1000, "<=" & EOMONTH(P39, 0)) -> 0
A40: Cash sum and subtract until cell 300. update if needed | E40: 19 | F40: 46348 | H40: 10000 | I40: 2083.62 | J40: =SUM(H40:I40) -> 12083.62 | K40: =IF(F40<=TODAY(),"Check!","Waiting") -> Waiting | M40: الراسيات ريزدينس 35# | N40: 14.2 | P40: 46935 | Q40: =SUMIFS(J$2:J$1000, F$2:F$1000, ">=" & DATE(YEAR(P40), MONTH(P40), 1), F$2:F$1000, "<=" & EOMONTH(P40, 0)) -> 0
...

Sheet MANAFA
A1: قيمة المحفظة | C1: الكاش | E1: المدة | F1: تاريخ الأستحقاق | G1: تاريخ السداد | H1: القيمة الأسمية | I1: صافي الربح | J1: الدفعة | K1: الحالة | L1: C | M1: أسم الصك | N1: النسبة السنوية | P1: الشهر | Q1: التدفقات | R1: CHECKLIST
A2: =SUMIFS(J2:J300,F2:F300,"<>")+B19+A19+C2 -> 99426.24 | C2: 0 | E2: 4 | G2: 45456 | H2: 1000 | I2: 12.56 | J2: =SUM(H2:I2) -> 1012.56 | K2: PAID | L2: EARLY | M2: 4873-3983 | N2: 14.1 | P2: 45778 | Q2: =SUMIFS(J$2:J$1000, F$2:F$1000, ">=" & DATE(YEAR(P2), MONTH(P2), 1), F$2:F$1000, "<=" & EOMONTH(P2, 0)) -> 0
E3: 5 | G3: 45484 | H3: 1000 | I3: 21.91 | J3: =SUM(H3:I3) -> 1021.91 | K3: PAID | L3: EARLY | M3: / | N3: 14.3 | P3: 45809 | Q3: =SUMIFS(J$2:J$1000, F$2:F$1000, ">=" & DATE(YEAR(P3), MONTH(P3), 1), F$2:F$1000, "<=" & EOMONTH(P3, 0)) -> 0 | R3: بداية الأستثمار
A4: الملاحظات | E4: 4 | G4: 45489 | H4: 1000 | I4: 10.35 | J4: =SUM(H4:I4) -> 1010.35 | K4: PAID | L4: EARLY | M4: / | N4: 13.65 | P4: 45839 | Q4: =SUMIFS(J$2:J$1000, F$2:F$1000, ">=" & DATE(YEAR(P4), MONTH(P4), 1), F$2:F$1000, "<=" & EOMONTH(P4, 0)) -> 0 | R4: اضف معلومات الاستثمار
E5: 4 | G5: 45495 | H5: 1000 | I5: 23.74 | J5: =SUM(H5:I5) -> 1023.74 | K5: PAID | L5: EARLY | M5: / | N5: 14.04 | P5: 45870 | Q5: =SUMIFS(J$2:J$1000, F$2:F$1000, ">=" & DATE(YEAR(P5), MONTH(P5), 1), F$2:F$1000, "<=" & EOMONTH(P5, 0)) -> 0 | R5: اخصم المبلغ من الكاش
E6: 4 | G6: 45522 | H6: 1000 | I6: 35.5 | J6: =SUM(H6:I6) -> 1035.5 | K6: PAID | L6: EARLY | M6: / | N6: 14.67 | P6: 45901 | Q6: =SUMIFS(J$2:J$1000, F$2:F$1000, ">=" & DATE(YEAR(P6), MONTH(P6), 1), F$2:F$1000, "<=" & EOMONTH(P6, 0)) -> 0 | R6: انسخة كاملة السطر الى ALL
E7: 4 | G7: 45532 | H7: 1000 | I7: 35.89 | J7: =SUM(H7:I7) -> 1035.89 | K7: PAID | L7: EARLY | M7: / | N7: 14.49 | P7: 45931 | Q7: =SUMIFS(J$2:J$1000, F$2:F$1000, ">=" & DATE(YEAR(P7), MONTH(P7), 1), F$2:F$1000, "<=" & EOMONTH(P7, 0)) -> 0 | R7: تحقق من التدفقات
E8: 3 | G8: 45536 | H8: 1000 | I8: 28.19 | J8: =SUM(H8:I8) -> 1028.19 | K8: PAID | M8: / | N8: 14.64 | P8: 45962 | Q8: =SUMIFS(J$2:J$1000, F$2:F$1000, ">=" & DATE(YEAR(P8), MONTH(P8), 1), F$2:F$1000, "<=" & EOMONTH(P8, 0)) -> 10280.28
E9: 6 | G9: 45537 | H9: 1000 | I9: 37.4 | J9: =SUM(H9:I9) -> 1037.4 | K9: PAID | L9: EARLY | M9: / | N9: 14.08 | P9: 45992 | Q9: =SUMIFS(J$2:J$1000, F$2:F$1000, ">=" & DATE(YEAR(P9), MONTH(P9), 1), F$2:F$1000, "<=" & EOMONTH(P9, 0)) -> 0
E10: 4 | G10: 45537 | H10: 1000 | I10: 29.9 | J10: =SUM(H10:I10) -> 1029.9 | K10: PAID | L10: EARLY | M10: / | N10: 14.67 | P10: 46023 | Q10: =SUMIFS(J$2:J$1000, F$2:F$1000, ">=" & DATE(YEAR(P10), MONTH(P10), 1), F$2:F$1000, "<=" & EOMONTH(P10, 0)) -> 10463.54 | R10: نهاية الأستثمار
A11: جميع الأرقام تم التأكد منها | E11: 3 | G11: 45538 | H11: 1000 | I11: 27.42 | J11: =SUM(H11:I11) -> 1027.42 | K11: PAID | M11: / | N11: 14.24 | P11: 46054 | Q11: =SUMIFS(J$2:J$1000, F$2:F$1000, ">=" & DATE(YEAR(P11), MONTH(P11), 1), F$2:F$1000, "<=" & EOMONTH(P11, 0)) -> 42216.06 | R11: PAID
A12: تم التأكد من السداد المبكر | E12: 4 | G12: 45543 | H12: 1000 | I12: 37.52 | J12: =SUM(H12:I12) -> 1037.52 | K12: PAID | L12: EARLY | M12: / | N12: 15.06 | P12: 46082 | Q12: =SUMIFS(J$2:J$1000, F$2:F$1000, ">=" & DATE(YEAR(P12), MONTH(P12), 1), F$2:F$1000, "<=" & EOMONTH(P12, 0)) -> 0 | R12: غير مكان تاريخ الاستحقاق الى تاريخ السداد
A13: مطلوب : التأكد من جميع التأخيرات | E13: 4 | G13: 45552 | H13: 1000 | I13: 31.25 | J13: =SUM(H13:I13) -> 1031.25 | K13: PAID | L13: EARLY | M13: / | N13: 12.9 | P13: 46113 | Q13: =SUMIFS(J$2:J$1000, F$2:F$1000, ">=" & DATE(YEAR(P13), MONTH(P13), 1), F$2:F$1000, "<=" & EOMONTH(P13, 0)) -> 0 | R13: غير صافي الربح
E14: 5 | G14: 45564 | H14: 1000 | I14: 43.7 | J14: =SUM(H14:I14) -> 1043.7 | K14: PAID | L14: EARLY | M14: / | N14: 13.8 | P14: 46143 | Q14: =SUMIFS(J$2:J$1000, F$2:F$1000, ">=" & DATE(YEAR(P14), MONTH(P14), 1), F$2:F$1000, "<=" & EOMONTH(P14, 0)) -> 0 | R14: اكتب / EARLY OR LATE OR DEF
E15: 4 | G15: 45565 | H15: 1000 | I15: 75.16 | J15: =SUM(H15:I15) -> 1075.16 | K15: PAID | L15: EARLY | M15: / | N15: 14.64 | P15: 46174 | Q15: =SUMIFS(J$2:J$1000, F$2:F$1000, ">=" & DATE(YEAR(P15), MONTH(P15), 1), F$2:F$1000, "<=" & EOMONTH(P15, 0)) -> 0 | R15: اضف مبلغ الدفعة الى الكاش
E16: 5 | G16: 45565 | H16: 2000 | I16: 46.6 | J16: =SUM(H16:I16) -> 2046.6 | K16: PAID | M16: / | N16: 14.54 | P16: 46204 | Q16: =SUMIFS(J$2:J$1000, F$2:F$1000, ">=" & DATE(YEAR(P16), MONTH(P16), 1), F$2:F$1000, "<=" & EOMONTH(P16, 0)) -> 0 | R16: انسخ كامل السطر الى ALL
E17: 5 | G17: 45566 | H17: 1000 | I17: 47.5 | J17: =SUM(H17:I17) -> 1047.5 | K17: PAID | M17: / | N17: 14.66 | P17: 46235 | Q17: =SUMIFS(J$2:J$1000, F$2:F$1000, ">=" & DATE(YEAR(P17), MONTH(P17), 1), F$2:F$1000, "<=" & EOMONTH(P17, 0)) -> 0
E18: 5 | G18: 45566 | H18: 1000 | I18: 37.1 | J18: =SUM(H18:I18) -> 1037.1 | K18: PAID | L18: EARLY | M18: / | N18: 14.23 | P18: 46266 | Q18: =SUMIFS(J$2:J$1000, F$2:F$1000, ">=" & DATE(YEAR(P18), MONTH(P18), 1), F$2:F$1000, "<=" & EOMONTH(P18, 0)) -> 0
A19: 0 | B19: -1.64 | C19: تصحيح الفواصل | E19: 6 | G19: 45578 | H19: 1000 | I19: 43.69 | J19: =SUM(H19:I19) -> 1043.69 | K19: PAID | L19: EARLY | M19: / | N19: 12.44 | P19: 46296 | Q19: =SUMIFS(J$2:J$1000, F$2:F$1000, ">=" & DATE(YEAR(P19), MONTH(P19), 1), F$2:F$1000, "<=" & EOMONTH(P19, 0)) -> 0
E20: 6 | G20: 45585 | H20: 1000 | I20: 55.98 | J20: =SUM(H20:I20) -> 1055.98 | K20: PAID | L20: EARLY | M20: / | N20: 14.7 | P20: 46327 | Q20: =SUMIFS(J$2:J$1000, F$2:F$1000, ">=" & DATE(YEAR(P20), MONTH(P20), 1), F$2:F$1000, "<=" & EOMONTH(P20, 0)) -> 0
A21: المأشرات | E21: 4 | G21: 45586 | H21: 1000 | I21: 34.19 | J21: =SUM(H21:I21) -> 1034.19 | K21: PAID | M21: / | N21: 13.32 | P21: 46357 | Q21: =SUMIFS(J$2:J$1000, F$2:F$1000, ">=" & DATE(YEAR(P21), MONTH(P21), 1), F$2:F$1000, "<=" & EOMONTH(P21, 0)) -> 0
A22: القيمة الأسمية | B22: صافي الأرباح | C22: عدد الأستثمارات | E22: 6 | G22: 45592 | H22: 1000 | I22: 52.56 | J22: =SUM(H22:I22) -> 1052.56 | K22: PAID | L22: EARLY | M22: / | N22: 13.8 | P22: 46388 | Q22: =SUMIFS(J$2:J$1000, F$2:F$1000, ">=" & DATE(YEAR(P22), MONTH(P22), 1), F$2:F$1000, "<=" & EOMONTH(P22, 0)) -> 0
A23: =SUMIFS(H2:H300,F2:F300,"<>") -> 90000 | B23: =SUMIFS(I2:I300,F2:F300,"<>") -> 9427.88 | C23: =COUNT(N2:N300, "?*") -> 107 | E23: 5 | G23: 45593 | H23: 5000 | I23: 200.2 | J23: =SUM(H23:I23) -> 5200.2 | K23: PAID | M23: / | N23: 12.48 | P23: 46419 | Q23: =SUMIFS(J$2:J$1000, F$2:F$1000, ">=" & DATE(YEAR(P23), MONTH(P23), 1), F$2:F$1000, "<=" & EOMONTH(P23, 0)) -> 0
A24: العائد السنوي ( APR ) | B24: العائد على الاستثمار ( ROI ) | C24: متوسط المدة ( بالشهر ) | E24: 5 | G24: 45593 | H24: 1000 | I24: 40.4 | J24: =SUM(H24:I24) -> 1040.4 | K24: PAID | M24: / | N24: 12.48 | P24: 46447 | Q24: =SUMIFS(J$2:J$1000, F$2:F$1000, ">=" & DATE(YEAR(P24), MONTH(P24), 1), F$2:F$1000, "<=" & EOMONTH(P24, 0)) -> 0
A25: =AVERAGE(N2:N500) -> 14.123364 | B25: =TEXT(B23/A23, "0.00%") -> 10.48% | C25: =SUMPRODUCT(H2:H500, E2:E500) / SUM(H2:H500) -> 5.7829314 | E25: 5 | G25: 45595 | H25: 1000 | I25: 46.97 | J25: =SUM(H25:I25) -> 1046.97 | K25: PAID | M25: / | N25: 14.64 | P25: 46478 | Q25: =SUMIFS(J$2:J$1000, F$2:F$1000, ">=" & DATE(YEAR(P25), MONTH(P25), 1), F$2:F$1000, "<=" & EOMONTH(P25, 0)) -> 0
A26: الفرص المتأخرة | B26: الفرص النشطة | C26: الفرص المكتملة | E26: 3 | G26: 45596 | H26: 1000 | I26: 48.77 | J26: =SUM(H26:I26) -> 1048.77 | K26: PAID | L26: EARLY | M26: / | N26: 13.24 | P26: 46508 | Q26: =SUMIFS(J$2:J$1000, F$2:F$1000, ">=" & DATE(YEAR(P26), MONTH(P26), 1), F$2:F$1000, "<=" & EOMONTH(P26, 0)) -> 0
A27: =COUNTIF(K2:K300, "CHECK!") -> 0 | B27: =COUNTIF(K2:K300, "WAITING") -> 8 | C27: =COUNTIF(K2:K300, "PAID") -> 99 | E27: 7 | G27: 45596 | H27: 1000 | I27: 47.3 | J27: =SUM(H27:I27) -> 1047.3 | K27: PAID | L27: EARLY | M27: / | N27: 14.66 | P27: 46539 | Q27: =SUMIFS(J$2:J$1000, F$2:F$1000, ">=" & DATE(YEAR(P27), MONTH(P27), 1), F$2:F$1000, "<=" & EOMONTH(P27, 0)) -> 0
E28: 6 | G28: 45596 | H28: 2000 | I28: 46.94 | J28: =SUM(H28:I28) -> 2046.94 | K28: PAID | L28: EARLY | M28: / | N28: 14.66 | P28: 46569 | Q28: =SUMIFS(J$2:J$1000, F$2:F$1000, ">=" & DATE(YEAR(P28), MONTH(P28), 1), F$2:F$1000, "<=" & EOMONTH(P28, 0)) -> 0
E29: 4 | G29: 45600 | H29: 5000 | I29: 151.96 | J29: =SUM(H29:I29) -> 5151.96 | K29: PAID | L29: EARLY | M29: / | N29: 13.74 | P29: 46600 | Q29: =SUMIFS(J$2:J$1000, F$2:F$1000, ">=" & DATE(YEAR(P29), MONTH(P29), 1), F$2:F$1000, "<=" & EOMONTH(P29, 0)) -> 36468
A30: القيمة الأسمية المدفوعة | B30: صافي الأرباح المدفوع | C30: المجموع | E30: 5 | G30: 45601 | H30: 1000 | I30: 45.75 | J30: =SUM(H30:I30) -> 1045.75 | K30: PAID | L30: EARLY | M30: / | N30: 14.74 | P30: 46631 | Q30: =SUMIFS(J$2:J$1000, F$2:F$1000, ">=" & DATE(YEAR(P30), MONTH(P30), 1), F$2:F$1000, "<=" & EOMONTH(P30, 0)) -> 0
A31: =SUMIFS(H2:H167,G2:G167,"<>") -> 449000 | B31: =SUMIFS(I2:I167,G2:G167,"<>") -> 18578.66 | C31: =A31+B31 -> 467578.66 | E31: 6 | G31: 45602 | H31: 1000 | I31: 51.9 | J31: =SUM(H31:I31) -> 1051.9 | K31: PAID | M31: / | N31: 13.48 | P31: 46661 | Q31: =SUMIFS(J$2:J$1000, F$2:F$1000, ">=" & DATE(YEAR(P31), MONTH(P31), 1), F$2:F$1000, "<=" & EOMONTH(P31, 0)) -> 0
A32: المجموع | E32: 5 | G32: 45606 | H32: 1000 | I32: 82.56 | J32: =SUM(H32:I32) -> 1082.56 | K32: PAID | L32: EARLY | M32: / | N32: 12.86 | P32: 46692 | Q32: =SUMIFS(J$2:J$1000, F$2:F$1000, ">=" & DATE(YEAR(P32), MONTH(P32), 1), F$2:F$1000, "<=" & EOMONTH(P32, 0)) -> 0
A33: HOW TO USE: | E33: 7 | G33: 45627 | H33: 1000 | I33: 52.42 | J33: =SUM(H33:I33) -> 1052.42 | K33: PAID | L33: EARLY | M33: / | N33: 12.93 | P33: 46722 | Q33: =SUMIFS(J$2:J$1000, F$2:F$1000, ">=" & DATE(YEAR(P33), MONTH(P33), 1), F$2:F$1000, "<=" & EOMONTH(P33, 0)) -> 0
A34: In the Due culum, when the date come it will change to red | E34: 5 | G34: 45606 | H34: 2000 | I34: 82.56 | J34: =SUM(H34:I34) -> 2082.56 | K34: PAID | M34: / | N34: 12.86 | P34: 46753 | Q34: =SUMIFS(J$2:J$1000, F$2:F$1000, ">=" & DATE(YEAR(P34), MONTH(P34), 1), F$2:F$1000, "<=" & EOMONTH(P34, 0)) -> 0
A35: if its PAID, then type the Paiment date = this will compute the profits | E35: 4 | G35: 45606 | H35: 4000 | I35: 128.2 | J35: =SUM(H35:I35) -> 4128.2 | K35: PAID | M35: / | N35: 14.04 | P35: 46784 | Q35: =SUMIFS(J$2:J$1000, F$2:F$1000, ">=" & DATE(YEAR(P35), MONTH(P35), 1), F$2:F$1000, "<=" & EOMONTH(P35, 0)) -> 0
A36: automatically in the portfolio value | E36: 5 | G36: 45609 | H36: 1000 | I36: 46.13 | J36: =SUM(H36:I36) -> 1046.13 | K36: PAID | M36: / | N36: 14.38 | P36: 46813 | Q36: =SUMIFS(J$2:J$1000, F$2:F$1000, ">=" & DATE(YEAR(P36), MONTH(P36), 1), F$2:F$1000, "<=" & EOMONTH(P36, 0)) -> 0
A37: then type (PAID) to change to green | E37: 4 | G37: 45615 | H37: 10000 | I37: 318.2 | J37: =SUM(H37:I37) -> 10318.2 | K37: PAID | M37: / | N37: 12.39 | P37: 46844 | Q37: =SUMIFS(J$2:J$1000, F$2:F$1000, ">=" & DATE(YEAR(P37), MONTH(P37), 1), F$2:F$1000, "<=" & EOMONTH(P37, 0)) -> 0
E38: 3 | G38: 45624 | H38: 5000 | I38: 119.24 | J38: =SUM(H38:I38) -> 5119.24 | K38: PAID | L38: EARLY | M38: / | N38: 12.8 | P38: 46874 | Q38: =SUMIFS(J$2:J$1000, F$2:F$1000, ">=" & DATE(YEAR(P38), MONTH(P38), 1), F$2:F$1000, "<=" & EOMONTH(P38, 0)) -> 0
A39: Note | E39: 6 | G39: 45627 | H39: 1000 | I39: 52.27 | J39: =SUM(H39:I39) -> 1052.27 | K39: PAID | L39: EARLY | M39: / | N39: 13.8 | P39: 46905 | Q39: =SUMIFS(J$2:J$1000, F$2:F$1000, ">=" & DATE(YEAR(P39), MONTH(P39), 1), F$2:F$1000, "<=" & EOMONTH(P39, 0)) -> 0
A40: Cash sum and subtract until cell 300. update if needed | E40: 5 | G40: 45628 | H40: 5000 | I40: 212.8 | J40: =SUM(H40:I40) -> 5212.8 | K40: PAID | L40: EARLY | M40: / | N40: 14.5 | P40: 46935 | Q40: =SUMIFS(J$2:J$1000, F$2:F$1000, ">=" & DATE(YEAR(P40), MONTH(P40), 1), F$2:F$1000, "<=" & EOMONTH(P40, 0)) -> 0
...

Sheet DINAR
A1: قيمة المحفظة | C1: الكاش | E1: المدة | F1: تاريخ الأستحقاق | G1: تاريخ السداد | H1: القيمة الأسمية | I1: صافي الربح | J1: الدفعة | K1: الحالة | L1: C | M1: أسم الصك | N1: النسبة السنوية | P1: الشهر | Q1: التدفقات | R1: CHECKLIST
A2: =SUMIFS(J2:J300,F2:F300,"<>")+B19+A19+C2 -> 71925.5 | C2: 0 | E2: 9 | F2: 45716 | H2: 5000 | I2: 585 | J2: =SUM(H2:I2) -> 5585 | K2: =IF(F2<=TODAY(),"Check!","Waiting") -> Check! | L2: DEFF | M2: 0522-236 | N2: 15.6 | P2: 45778 | Q2: =SUMIFS(J$2:J$1000, F$2:F$1000, ">=" & DATE(YEAR(P2), MONTH(P2), 1), F$2:F$1000, "<=" & EOMONTH(P2, 0)) -> 0
E3: 30 | F3: 46374 | H3: 5000 | I3: 2297.5 | J3: =SUM(H3:I3) -> 7297.5 | K3: =IF(F3<=TODAY(),"Check!","Waiting") -> Waiting | M3: 1901-230 | N3: 18.38 | P3: 45809 | Q3: =SUMIFS(J$2:J$1000, F$2:F$1000, ">=" & DATE(YEAR(P3), MONTH(P3), 1), F$2:F$1000, "<=" & EOMONTH(P3, 0)) -> 0 | R3: بداية الأستثمار
A4: الملاحظات | E4: 9 | G4: 45763 | H4: 5000 | I4: 622.5 | J4: =SUM(H4:I4) -> 5622.5 | K4: PAID | M4: 0110-250 | N4: 16.6 | P4: 45839 | Q4: =SUMIFS(J$2:J$1000, F$2:F$1000, ">=" & DATE(YEAR(P4), MONTH(P4), 1), F$2:F$1000, "<=" & EOMONTH(P4, 0)) -> 0 | R4: اضف معلومات الاستثمار
E5: 6 | G5: 45678 | H5: 5000 | I5: 401.5 | J5: =SUM(H5:I5) -> 5401.5 | K5: PAID | M5: 0201-283 | N5: 16.06 | P5: 45870 | Q5: =SUMIFS(J$2:J$1000, F$2:F$1000, ">=" & DATE(YEAR(P5), MONTH(P5), 1), F$2:F$1000, "<=" & EOMONTH(P5, 0)) -> 0 | R5: اخصم المبلغ من الكاش
E6: 15 | F6: 46093 | H6: 5000 | I6: 937.5 | J6: =SUM(H6:I6) -> 5937.5 | K6: =IF(F6<=TODAY(),"Check!","Waiting") -> Waiting | M6: 0401-296 | N6: 15 | P6: 45901 | Q6: =SUMIFS(J$2:J$1000, F$2:F$1000, ">=" & DATE(YEAR(P6), MONTH(P6), 1), F$2:F$1000, "<=" & EOMONTH(P6, 0)) -> 0 | R6: انسخة كاملة السطر الى ALL
B7: تأخر الفرص | E7: 18 | F7: 46198 | H7: 5000 | I7: 1183.5 | J7: =SUM(H7:I7) -> 6183.5 | K7: =IF(F7<=TODAY(),"Check!","Waiting") -> Waiting | M7: 0522-327 | N7: 15.78 | P7: 45931 | Q7: =SUMIFS(J$2:J$1000, F$2:F$1000, ">=" & DATE(YEAR(P7), MONTH(P7), 1), F$2:F$1000, "<=" & EOMONTH(P7, 0)) -> 0 | R7: تحقق من التدفقات
B8: التطبيق سيء | E8: 21 | F8: 46541 | H8: 10000 | I8: 287 | J8: =SUM(H8:I8) -> 10287 | K8: =IF(F8<=TODAY(),"Check!","Waiting") -> Waiting | M8: محمد الحرفي للمقاولات | N8: 16.4 | P8: 45962 | Q8: =SUMIFS(J$2:J$1000, F$2:F$1000, ">=" & DATE(YEAR(P8), MONTH(P8), 1), F$2:F$1000, "<=" & EOMONTH(P8, 0)) -> 0
A9: مطلوب : التأكد من جميع التأخيرات | E9: 18 | F9: 46513 | H9: 10000 | I9: 2415 | J9: =SUM(H9:I9) -> 12415 | K9: =IF(F9<=TODAY(),"Check!","Waiting") -> Waiting | M9: معدل للتصميم | N9: 16.1 | P9: 45992 | Q9: =SUMIFS(J$2:J$1000, F$2:F$1000, ">=" & DATE(YEAR(P9), MONTH(P9), 1), F$2:F$1000, "<=" & EOMONTH(P9, 0)) -> 0
A10: مطلوب : التأكد من جميع السداد المبكر | E10: 15 | F10: 46429 | H10: 20000 | I10: 4220 | J10: =SUM(H10:I10) -> 24220 | K10: =IF(F10<=TODAY(),"Check!","Waiting") -> Waiting | M10: الهيثم للتعدين | N10: 16.88 | P10: 46023 | Q10: =SUMIFS(J$2:J$1000, F$2:F$1000, ">=" & DATE(YEAR(P10), MONTH(P10), 1), F$2:F$1000, "<=" & EOMONTH(P10, 0)) -> 0 | R10: نهاية الأستثمار
B11: مزكاه | P11: 46054 | Q11: =SUMIFS(J$2:J$1000, F$2:F$1000, ">=" & DATE(YEAR(P11), MONTH(P11), 1), F$2:F$1000, "<=" & EOMONTH(P11, 0)) -> 0 | R11: PAID
P12: 46082 | Q12: =SUMIFS(J$2:J$1000, F$2:F$1000, ">=" & DATE(YEAR(P12), MONTH(P12), 1), F$2:F$1000, "<=" & EOMONTH(P12, 0)) -> 5937.5 | R12: غير مكان تاريخ الاستحقاق الى تاريخ السداد
A13: جميع الأرقام تم التأكد منها | P13: 46113 | Q13: =SUMIFS(J$2:J$1000, F$2:F$1000, ">=" & DATE(YEAR(P13), MONTH(P13), 1), F$2:F$1000, "<=" & EOMONTH(P13, 0)) -> 0 | R13: غير صافي الربح
A14: ولاكن تم توزيع 1276.5 وهي غير مذكورة في صافي الربح | P14: 46143 | Q14: =SUMIFS(J$2:J$1000, F$2:F$1000, ">=" & DATE(YEAR(P14), MONTH(P14), 1), F$2:F$1000, "<=" & EOMONTH(P14, 0)) -> 0 | R14: اكتب / EARLY OR LATE OR DEF
P15: 46174 | Q15: =SUMIFS(J$2:J$1000, F$2:F$1000, ">=" & DATE(YEAR(P15), MONTH(P15), 1), F$2:F$1000, "<=" & EOMONTH(P15, 0)) -> 6183.5 | R15: اضف مبلغ الدفعة الى الكاش
P16: 46204 | Q16: =SUMIFS(J$2:J$1000, F$2:F$1000, ">=" & DATE(YEAR(P16), MONTH(P16), 1), F$2:F$1000, "<=" & EOMONTH(P16, 0)) -> 0 | R16: انسخ كامل السطر الى ALL
P17: 46235 | Q17: =SUMIFS(J$2:J$1000, F$2:F$1000, ">=" & DATE(YEAR(P17), MONTH(P17), 1), F$2:F$1000, "<=" & EOMONTH(P17, 0)) -> 0
P18: 46266 | Q18: =SUMIFS(J$2:J$1000, F$2:F$1000, ">=" & DATE(YEAR(P18), MONTH(P18), 1), F$2:F$1000, "<=" & EOMONTH(P18, 0)) -> 0
A19: 0 | B19: 0 | C19: تصحيح الفواصل | P19: 46296 | Q19: =SUMIFS(J$2:J$1000, F$2:F$1000, ">=" & DATE(YEAR(P19), MONTH(P19), 1), F$2:F$1000, "<=" & EOMONTH(P19, 0)) -> 0
P20: 46327 | Q20: =SUMIFS(J$2:J$1000, F$2:F$1000, ">=" & DATE(YEAR(P20), MONTH(P20), 1), F$2:F$1000, "<=" & EOMONTH(P20, 0)) -> 0
A21: المأشرات | P21: 46357 | Q21: =SUMIFS(J$2:J$1000, F$2:F$1000, ">=" & DATE(YEAR(P21), MONTH(P21), 1), F$2:F$1000, "<=" & EOMONTH(P21, 0)) -> 7297.5
A22: القيمة الأسمية | B22: صافي الأرباح | C22: عدد الأستثمارات | P22: 46388 | Q22: =SUMIFS(J$2:J$1000, F$2:F$1000, ">=" & DATE(YEAR(P22), MONTH(P22), 1), F$2:F$1000, "<=" & EOMONTH(P22, 0)) -> 0
A23: =SUMIFS(H2:H167,F2:F167,"<>") -> 60000 | B23: =SUMIFS(I2:I300,F2:F300,"<>") -> 11925.5 | C23: =COUNT(N2:N300, "?*") -> 9 | P23: 46419 | Q23: =SUMIFS(J$2:J$1000, F$2:F$1000, ">=" & DATE(YEAR(P23), MONTH(P23), 1), F$2:F$1000, "<=" & EOMONTH(P23, 0)) -> 24220
A24: العائد السنوي ( APR ) | B24: العائد على الاستثمار ( ROI ) | C24: متوسط المدة ( بالشهر ) | P24: 46447 | Q24: =SUMIFS(J$2:J$1000, F$2:F$1000, ">=" & DATE(YEAR(P24), MONTH(P24), 1), F$2:F$1000, "<=" & EOMONTH(P24, 0)) -> 0
A25: =AVERAGE(N2:N500) -> 16.311111 | B25: =TEXT(B23/A23, "0.00%") -> 19.88% | C25: =SUMPRODUCT(H2:H500, E2:E500) / SUM(H2:H500) -> 16.071429 | P25: 46478 | Q25: =SUMIFS(J$2:J$1000, F$2:F$1000, ">=" & DATE(YEAR(P25), MONTH(P25), 1), F$2:F$1000, "<=" & EOMONTH(P25, 0)) -> 0
A26: الفرص المتأخرة | B26: الفرص النشطة | C26: الفرص المكتملة | P26: 46508 | Q26: =SUMIFS(J$2:J$1000, F$2:F$1000, ">=" & DATE(YEAR(P26), MONTH(P26), 1), F$2:F$1000, "<=" & EOMONTH(P26, 0)) -> 12415
A27: =COUNTIF(K2:K300, "CHECK!") -> 1 | B27: =COUNTIF(K2:K300, "WAITING") -> 6 | C27: =COUNTIF(K2:K300, "Paid") -> 2 | P27: 46539 | Q27: =SUMIFS(J$2:J$1000, F$2:F$1000, ">=" & DATE(YEAR(P27), MONTH(P27), 1), F$2:F$1000, "<=" & EOMONTH(P27, 0)) -> 10287
P28: 46569 | Q28: =SUMIFS(J$2:J$1000, F$2:F$1000, ">=" & DATE(YEAR(P28), MONTH(P28), 1), F$2:F$1000, "<=" & EOMONTH(P28, 0)) -> 0
P29: 46600 | Q29: =SUMIFS(J$2:J$1000, F$2:F$1000, ">=" & DATE(YEAR(P29), MONTH(P29), 1), F$2:F$1000, "<=" & EOMONTH(P29, 0)) -> 0
A30: القيمة الأسمية المدفوعة | B30: صافي الأرباح المدفوع | C30: المجموع | P30: 46631 | Q30: =SUMIFS(J$2:J$1000, F$2:F$1000, ">=" & DATE(YEAR(P30), MONTH(P30), 1), F$2:F$1000, "<=" & EOMONTH(P30, 0)) -> 0
A31: =SUMIFS(H2:H167,G2:G167,"<>") -> 10000 | B31: =SUMIFS(I2:I167,G2:G167,"<>") -> 1024 | C31: =A31+B31 -> 11024 | P31: 46661 | Q31: =SUMIFS(J$2:J$1000, F$2:F$1000, ">=" & DATE(YEAR(P31), MONTH(P31), 1), F$2:F$1000, "<=" & EOMONTH(P31, 0)) -> 0
A32: المجموع | P32: 46692 | Q32: =SUMIFS(J$2:J$1000, F$2:F$1000, ">=" & DATE(YEAR(P32), MONTH(P32), 1), F$2:F$1000, "<=" & EOMONTH(P32, 0)) -> 0
A33: HOW TO USE: | P33: 46722 | Q33: =SUMIFS(J$2:J$1000, F$2:F$1000, ">=" & DATE(YEAR(P33), MONTH(P33), 1), F$2:F$1000, "<=" & EOMONTH(P33, 0)) -> 0
A34: In the Due culum, when the date come it will change to red | P34: 46753 | Q34: =SUMIFS(J$2:J$1000, F$2:F$1000, ">=" & DATE(YEAR(P34), MONTH(P34), 1), F$2:F$1000, "<=" & EOMONTH(P34, 0)) -> 0
A35: if its Paid, then type the Paiment date = this will compute the profits | P35: 46784 | Q35: =SUMIFS(J$2:J$1000, F$2:F$1000, ">=" & DATE(YEAR(P35), MONTH(P35), 1), F$2:F$1000, "<=" & EOMONTH(P35, 0)) -> 0
A36: automatically in the portfolio value | P36: 46813 | Q36: =SUMIFS(J$2:J$1000, F$2:F$1000, ">=" & DATE(YEAR(P36), MONTH(P36), 1), F$2:F$1000, "<=" & EOMONTH(P36, 0)) -> 0
A37: then type (Paid) to change to green | P37: 46844 | Q37: =SUMIFS(J$2:J$1000, F$2:F$1000, ">=" & DATE(YEAR(P37), MONTH(P37), 1), F$2:F$1000, "<=" & EOMONTH(P37, 0)) -> 0
P38: 46874 | Q38: =SUMIFS(J$2:J$1000, F$2:F$1000, ">=" & DATE(YEAR(P38), MONTH(P38), 1), F$2:F$1000, "<=" & EOMONTH(P38, 0)) -> 0
A39: Note | P39: 46905 | Q39: =SUMIFS(J$2:J$1000, F$2:F$1000, ">=" & DATE(YEAR(P39), MONTH(P39), 1), F$2:F$1000, "<=" & EOMONTH(P39, 0)) -> 0
A40: Cash sum and subtract until cell 300. update if needed | P40: 46935 | Q40: =SUMIFS(J$2:J$1000, F$2:F$1000, ">=" & DATE(YEAR(P40), MONTH(P40), 1), F$2:F$1000, "<=" & EOMONTH(P40, 0)) -> 0
...

Sheet LENDO
A1: قيمة المحفظة | C1: الكاش | E1: المدة | F1: تاريخ الأستحقاق | G1: تاريخ السداد | H1: القيمة الأسمية | I1: صافي الربح | J1: الدفعة | K1: الحالة | L1: C | M1: أسم الصك | N1: النسبة السنوية | P1: الشهر | Q1: التدفقات | R1: CHECKLIST
A2: =SUMIFS(J2:J300,F2:F300,"<>")+B19+A19+C2 -> 27321.49 | C2: 0 | E2: 3 | G2: 45479 | H2: 1000 | I2: 30.8 | J2: =SUM(H2:I2) -> 1030.8 | K2: PAID | M2: LN5301 | N2: 16 | P2: 45778 | Q2: =SUMIFS(J$2:J$1000, F$2:F$1000, ">=" & DATE(YEAR(P2), MONTH(P2), 1), F$2:F$1000, "<=" & EOMONTH(P2, 0)) -> 0
E3: 3 | G3: 45479 | H3: 1000 | I3: 21.17 | J3: =SUM(H3:I3) -> 1021.17 | K3: PAID | M3: / | N3: 11 | P3: 45809 | Q3: =SUMIFS(J$2:J$1000, F$2:F$1000, ">=" & DATE(YEAR(P3), MONTH(P3), 1), F$2:F$1000, "<=" & EOMONTH(P3, 0)) -> 1077 | R3: بداية الأستثمار
A4: الملاحظات | E4: 2 | G4: 45484 | H4: 1000 | I4: 19.25 | J4: =SUM(H4:I4) -> 1019.25 | K4: PAID | M4: / | N4: 15 | P4: 45839 | Q4: =SUMIFS(J$2:J$1000, F$2:F$1000, ">=" & DATE(YEAR(P4), MONTH(P4), 1), F$2:F$1000, "<=" & EOMONTH(P4, 0)) -> 0 | R4: اضف معلومات الاستثمار
E5: 4 | G5: 45509 | H5: 1000 | I5: 28.24 | J5: =SUM(H5:I5) -> 1028.24 | K5: PAID | M5: / | N5: 11 | P5: 45870 | Q5: =SUMIFS(J$2:J$1000, F$2:F$1000, ">=" & DATE(YEAR(P5), MONTH(P5), 1), F$2:F$1000, "<=" & EOMONTH(P5, 0)) -> 0 | R5: اخصم المبلغ من الكاش
E6: 3 | G6: 45525 | H6: 1000 | I6: 25.02 | J6: =SUM(H6:I6) -> 1025.02 | K6: PAID | M6: / | N6: 13 | P6: 45901 | Q6: =SUMIFS(J$2:J$1000, F$2:F$1000, ">=" & DATE(YEAR(P6), MONTH(P6), 1), F$2:F$1000, "<=" & EOMONTH(P6, 0)) -> 0 | R6: انسخة كاملة السطر الى ALL
A7: الفرص تتأخر دائما | B7: فرص سيءه جداا | E7: 5 | G7: 45546 | H7: 1000 | I7: 38.5 | J7: =SUM(H7:I7) -> 1038.5 | K7: PAID | M7: / | N7: 12 | P7: 45931 | Q7: =SUMIFS(J$2:J$1000, F$2:F$1000, ">=" & DATE(YEAR(P7), MONTH(P7), 1), F$2:F$1000, "<=" & EOMONTH(P7, 0)) -> 0 | R7: تحقق من التدفقات
A8: قلل من الأستثمار في المنصة | E8: 5 | G8: 45549 | H8: 5000 | I8: 224.59 | J8: =SUM(H8:I8) -> 5224.59 | K8: PAID | M8: / | N8: 14 | P8: 45962 | Q8: =SUMIFS(J$2:J$1000, F$2:F$1000, ">=" & DATE(YEAR(P8), MONTH(P8), 1), F$2:F$1000, "<=" & EOMONTH(P8, 0)) -> 0
E9: 5 | G9: 45554 | H9: 5000 | I9: 224.59 | J9: =SUM(H9:I9) -> 5224.59 | K9: PAID | M9: / | N9: 14 | P9: 45992 | Q9: =SUMIFS(J$2:J$1000, F$2:F$1000, ">=" & DATE(YEAR(P9), MONTH(P9), 1), F$2:F$1000, "<=" & EOMONTH(P9, 0)) -> 0
A10: القيمة الاسمية تم التأكد منها | E10: 5 | G10: 45554 | H10: 5000 | I10: 224.59 | J10: =SUM(H10:I10) -> 5224.59 | K10: PAID | M10: / | N10: 14 | P10: 46023 | Q10: =SUMIFS(J$2:J$1000, F$2:F$1000, ">=" & DATE(YEAR(P10), MONTH(P10), 1), F$2:F$1000, "<=" & EOMONTH(P10, 0)) -> 0 | R10: نهاية الأستثمار
A11: الأرباح فيه اختلاف بمقدار 423.4 | E11: 2 | G11: 45556 | H11: 1000 | I11: 19.25 | J11: =SUM(H11:I11) -> 1019.25 | K11: PAID | M11: / | N11: 15 | P11: 46054 | Q11: =SUMIFS(J$2:J$1000, F$2:F$1000, ">=" & DATE(YEAR(P11), MONTH(P11), 1), F$2:F$1000, "<=" & EOMONTH(P11, 0)) -> 0 | R11: PAID
A12: غالبا يرجع الى الفرص المسدده جزئيا | E12: 3 | G12: 45565 | H12: 1000 | I12: 26.95 | J12: =SUM(H12:I12) -> 1026.95 | K12: PAID | M12: / | N12: 14 | P12: 46082 | Q12: =SUMIFS(J$2:J$1000, F$2:F$1000, ">=" & DATE(YEAR(P12), MONTH(P12), 1), F$2:F$1000, "<=" & EOMONTH(P12, 0)) -> 0 | R12: غير مكان تاريخ الاستحقاق الى تاريخ السداد
E13: 6 | G13: 45569 | H13: 1000 | I13: 61.6 | J13: =SUM(H13:I13) -> 1061.6 | K13: PAID | M13: / | N13: 16 | P13: 46113 | Q13: =SUMIFS(J$2:J$1000, F$2:F$1000, ">=" & DATE(YEAR(P13), MONTH(P13), 1), F$2:F$1000, "<=" & EOMONTH(P13, 0)) -> 0 | R13: غير صافي الربح
A14: مطلوب : التأكد من جميع التأخيرات | E14: 4 | G14: 45572 | H14: 1000 | I14: 56.67 | J14: =SUM(H14:I14) -> 1056.67 | K14: PAID | M14: / | N14: 17 | P14: 46143 | Q14: =SUMIFS(J$2:J$1000, F$2:F$1000, ">=" & DATE(YEAR(P14), MONTH(P14), 1), F$2:F$1000, "<=" & EOMONTH(P14, 0)) -> 0 | R14: اكتب / EARLY OR LATE OR DEF
A15: مطلوب : التأكد من جميع السداد المبكر | E15: 2 | G15: 45577 | H15: 2000 | I15: 53.9 | J15: =SUM(H15:I15) -> 2053.9 | K15: PAID | M15: / | N15: 21 | P15: 46174 | Q15: =SUMIFS(J$2:J$1000, F$2:F$1000, ">=" & DATE(YEAR(P15), MONTH(P15), 1), F$2:F$1000, "<=" & EOMONTH(P15, 0)) -> 0 | R15: اضف مبلغ الدفعة الى الكاش
E16: 6 | G16: 45580 | H16: 1000 | I16: 63.52 | J16: =SUM(H16:I16) -> 1063.52 | K16: PAID | M16: / | N16: 16.5 | P16: 46204 | Q16: =SUMIFS(J$2:J$1000, F$2:F$1000, ">=" & DATE(YEAR(P16), MONTH(P16), 1), F$2:F$1000, "<=" & EOMONTH(P16, 0)) -> 0 | R16: انسخ كامل السطر الى ALL
E17: 6 | G17: 45584 | H17: 1000 | I17: 61.6 | J17: =SUM(H17:I17) -> 1061.6 | K17: PAID | L17: LATE | M17: / | N17: 16 | P17: 46235 | Q17: =SUMIFS(J$2:J$1000, F$2:F$1000, ">=" & DATE(YEAR(P17), MONTH(P17), 1), F$2:F$1000, "<=" & EOMONTH(P17, 0)) -> 0
E18: 3 | G18: 45586 | H18: 1000 | I18: 34.65 | J18: =SUM(H18:I18) -> 1034.65 | K18: PAID | M18: / | N18: 18 | P18: 46266 | Q18: =SUMIFS(J$2:J$1000, F$2:F$1000, ">=" & DATE(YEAR(P18), MONTH(P18), 1), F$2:F$1000, "<=" & EOMONTH(P18, 0)) -> 0
A19: 0 | B19: 0 | C19: تصحيح الفواصل | E19: 6 | G19: 45589 | H19: 1000 | I19: 57.75 | J19: =SUM(H19:I19) -> 1057.75 | K19: PAID | L19: LATE | M19: / | N19: 15 | P19: 46296 | Q19: =SUMIFS(J$2:J$1000, F$2:F$1000, ">=" & DATE(YEAR(P19), MONTH(P19), 1), F$2:F$1000, "<=" & EOMONTH(P19, 0)) -> 0
E20: 6 | G20: 45592 | H20: 1000 | I20: 53.9 | J20: =SUM(H20:I20) -> 1053.9 | K20: PAID | M20: / | N20: 14 | P20: 46327 | Q20: =SUMIFS(J$2:J$1000, F$2:F$1000, ">=" & DATE(YEAR(P20), MONTH(P20), 1), F$2:F$1000, "<=" & EOMONTH(P20, 0)) -> 0
A21: المأشرات | E21: 6 | G21: 45593 | H21: 1000 | I21: 53.9 | J21: =SUM(H21:I21) -> 1053.9 | K21: PAID | M21: / | N21: 14 | P21: 46357 | Q21: =SUMIFS(J$2:J$1000, F$2:F$1000, ">=" & DATE(YEAR(P21), MONTH(P21), 1), F$2:F$1000, "<=" & EOMONTH(P21, 0)) -> 0
A22: القيمة الأسمية | B22: صافي الأرباح | C22: عدد الأستثمارات | E22: 4 | G22: 45593 | H22: 1000 | I22: 41.06 | J22: =SUM(H22:I22) -> 1041.06 | K22: PAID | M22: / | N22: 16 | P22: 46388 | Q22: =SUMIFS(J$2:J$1000, F$2:F$1000, ">=" & DATE(YEAR(P22), MONTH(P22), 1), F$2:F$1000, "<=" & EOMONTH(P22, 0)) -> 0
A23: =SUMIFS(H2:H300,F2:F300,"<>") -> 26000 | B23: =SUMIFS(I2:I300,F2:F300,"<>") -> 1321.49 | C23: =COUNT(N2:N300, "?*") -> 87 | E23: 2 | G23: 45593 | H23: 3000 | I23: 53.9 | J23: =SUM(H23:I23) -> 3053.9 | K23: PAID | M23: / | N23: 14 | P23: 46419 | Q23: =SUMIFS(J$2:J$1000, F$2:F$1000, ">=" & DATE(YEAR(P23), MONTH(P23), 1), F$2:F$1000, "<=" & EOMONTH(P23, 0)) -> 0
A24: العائد السنوي ( APR ) | B24: العائد على الاستثمار ( ROI ) | C24: متوسط المدة ( بالشهر ) | E24: 2 | G24: 45593 | H24: 2000 | I24: 51.34 | J24: =SUM(H24:I24) -> 2051.34 | K24: PAID | L24: LATE | M24: / | N24: 20 | P24: 46447 | Q24: =SUMIFS(J$2:J$1000, F$2:F$1000, ">=" & DATE(YEAR(P24), MONTH(P24), 1), F$2:F$1000, "<=" & EOMONTH(P24, 0)) -> 0
B25: =TEXT(B23/A23, "0.00%") -> 5.08% | C25: =SUMPRODUCT(H2:H500, E2:E500) / SUM(H2:H500) -> 3.6864654 | E25: 6 | G25: 45594 | H25: 1000 | I25: 53.9 | J25: =SUM(H25:I25) -> 1053.9 | K25: PAID | M25: / | N25: 14 | P25: 46478 | Q25: =SUMIFS(J$2:J$1000, F$2:F$1000, ">=" & DATE(YEAR(P25), MONTH(P25), 1), F$2:F$1000, "<=" & EOMONTH(P25, 0)) -> 0
A26: الفرص المتأخرة | B26: الفرص النشطة | C26: الفرص المكتملة | E26: 3 | G26: 45598 | H26: 1000 | I26: 32.72 | J26: =SUM(H26:I26) -> 1032.72 | K26: PAID | M26: / | N26: 17 | P26: 46508 | Q26: =SUMIFS(J$2:J$1000, F$2:F$1000, ">=" & DATE(YEAR(P26), MONTH(P26), 1), F$2:F$1000, "<=" & EOMONTH(P26, 0)) -> 0
A27: =COUNTIF(K2:K300, "CHECK!") -> 11 | B27: =COUNTIF(K2:K300, "WAITING") -> 0 | C27: =COUNTIF(K2:K300, "Paid") -> 76 | E27: 3 | G27: 45599 | H27: 1000 | I27: 40.42 | J27: =SUM(H27:I27) -> 1040.42 | K27: PAID | M27: / | N27: 21 | P27: 46539 | Q27: =SUMIFS(J$2:J$1000, F$2:F$1000, ">=" & DATE(YEAR(P27), MONTH(P27), 1), F$2:F$1000, "<=" & EOMONTH(P27, 0)) -> 0
E28: 3 | G28: 45601 | H28: 3000 | I28: 103.95 | J28: =SUM(H28:I28) -> 3103.95 | K28: PAID | M28: / | N28: 18 | P28: 46569 | Q28: =SUMIFS(J$2:J$1000, F$2:F$1000, ">=" & DATE(YEAR(P28), MONTH(P28), 1), F$2:F$1000, "<=" & EOMONTH(P28, 0)) -> 0
E29: 2 | G29: 45605 | H29: 1000 | I29: 32.65 | J29: =SUM(H29:I29) -> 1032.65 | K29: PAID | M29: / | N29: 18 | P29: 46600 | Q29: =SUMIFS(J$2:J$1000, F$2:F$1000, ">=" & DATE(YEAR(P29), MONTH(P29), 1), F$2:F$1000, "<=" & EOMONTH(P29, 0)) -> 0
A30: القيمة الأسمية المدفوعة | B30: صافي الأرباح المدفوع | C30: المجموع | E30: 3 | G30: 45607 | H30: 2000 | I30: 57.75 | J30: =SUM(H30:I30) -> 2057.75 | K30: PAID | M30: / | N30: 15 | P30: 46631 | Q30: =SUMIFS(J$2:J$1000, F$2:F$1000, ">=" & DATE(YEAR(P30), MONTH(P30), 1), F$2:F$1000, "<=" & EOMONTH(P30, 0)) -> 0
A31: =SUMIFS(H2:H167,G2:G167,"<>") -> 179400 | B31: =SUMIFS(I2:I167,G2:G167,"<>") -> 7155.9 | C31: =A31+B31 -> 186555.9 | E31: 3 | G31: 45608 | H31: 1400 | I31: 48.51 | J31: =SUM(H31:I31) -> 1448.51 | K31: PAID | M31: / | N31: 18 | P31: 46661 | Q31: =SUMIFS(J$2:J$1000, F$2:F$1000, ">=" & DATE(YEAR(P31), MONTH(P31), 1), F$2:F$1000, "<=" & EOMONTH(P31, 0)) -> 0
A32: المجموع | E32: 4 | G32: 45608 | H32: 1000 | I32: 38.5 | J32: =SUM(H32:I32) -> 1038.5 | K32: PAID | M32: / | N32: 15 | P32: 46692 | Q32: =SUMIFS(J$2:J$1000, F$2:F$1000, ">=" & DATE(YEAR(P32), MONTH(P32), 1), F$2:F$1000, "<=" & EOMONTH(P32, 0)) -> 0
A33: HOW TO USE: | E33: 4 | G33: 45610 | H33: 1000 | I33: 48.76 | J33: =SUM(H33:I33) -> 1048.76 | K33: PAID | M33: / | N33: 19 | P33: 46722 | Q33: =SUMIFS(J$2:J$1000, F$2:F$1000, ">=" & DATE(YEAR(P33), MONTH(P33), 1), F$2:F$1000, "<=" & EOMONTH(P33, 0)) -> 0
A34: In the Due culum, when the date come it will change to red | E34: 4 | G34: 45610 | H34: 1000 | I34: 41.06 | J34: =SUM(H34:I34) -> 1041.06 | K34: PAID | M34: / | N34: 16 | P34: 46753 | Q34: =SUMIFS(J$2:J$1000, F$2:F$1000, ">=" & DATE(YEAR(P34), MONTH(P34), 1), F$2:F$1000, "<=" & EOMONTH(P34, 0)) -> 0
A35: if its Paid, then type the Paiment date = this will compute the profits | E35: 3 | G35: 45610 | H35: 5000 | I35: 225 | J35: =SUM(H35:I35) -> 5225 | K35: PAID | M35: / | N35: 18 | P35: 46784 | Q35: =SUMIFS(J$2:J$1000, F$2:F$1000, ">=" & DATE(YEAR(P35), MONTH(P35), 1), F$2:F$1000, "<=" & EOMONTH(P35, 0)) -> 0
A36: automatically in the portfolio value | E36: 3 | G36: 45613 | H36: 2000 | I36: 85 | J36: =SUM(H36:I36) -> 2085 | K36: PAID | M36: / | N36: 17 | P36: 46813 | Q36: =SUMIFS(J$2:J$1000, F$2:F$1000, ">=" & DATE(YEAR(P36), MONTH(P36), 1), F$2:F$1000, "<=" & EOMONTH(P36, 0)) -> 0
A37: then type (Paid) to change to green | E37: 3 | G37: 45623 | H37: 5000 | I37: 144.38 | J37: =SUM(H37:I37) -> 5144.38 | K37: PAID | M37: / | N37: 15 | P37: 46844 | Q37: =SUMIFS(J$2:J$1000, F$2:F$1000, ">=" & DATE(YEAR(P37), MONTH(P37), 1), F$2:F$1000, "<=" & EOMONTH(P37, 0)) -> 0
E38: 6 | G38: 45625 | H38: 1000 | I38: 53.9 | J38: =SUM(H38:I38) -> 1053.9 | K38: PAID | M38: / | N38: 14 | P38: 46874 | Q38: =SUMIFS(J$2:J$1000, F$2:F$1000, ">=" & DATE(YEAR(P38), MONTH(P38), 1), F$2:F$1000, "<=" & EOMONTH(P38, 0)) -> 0
A39: Note | E39: 5 | G39: 45632 | H39: 1000 | I39: 67.37 | J39: =SUM(H39:I39) -> 1067.37 | K39: PAID | M39: / | N39: 21 | P39: 46905 | Q39: =SUMIFS(J$2:J$1000, F$2:F$1000, ">=" & DATE(YEAR(P39), MONTH(P39), 1), F$2:F$1000, "<=" & EOMONTH(P39, 0)) -> 0
A40: Cash sum and subtract until cell 300. update if needed | E40: 5 | G40: 45632 | H40: 1000 | I40: 48.12 | J40: =SUM(H40:I40) -> 1048.12 | K40: PAID | M40: / | N40: 15 | P40: 46935 | Q40: =SUMIFS(J$2:J$1000, F$2:F$1000, ">=" & DATE(YEAR(P40), MONTH(P40), 1), F$2:F$1000, "<=" & EOMONTH(P40, 0)) -> 0
...

Sheet SAFQA
A1: قيمة المحفظة | C1: الكاش | E1: المدة | F1: تاريخ الأستحقاق | G1: تاريخ السداد | H1: القيمة الأسمية | I1: صافي الربح | J1: الدفعة | K1: الحالة | L1: C | M1: أسم الصك | N1: النسبة السنوية | P1: الشهر | Q1: التدفقات | R1: CHECKLIST
A2: =SUMIFS(J2:J300,F2:F300,"<>")+B19+A19+C2 -> 62379.69 | C2: 0 | E2: 17 | F2: 46312 | H2: 20000 | I2: 4086 | J2: =SUM(H2:I2) -> 24086 | K2: =IF(F2<=TODAY(),"Check!","Waiting") -> Waiting | M2: العجلان ريزدنت | N2: 14.42 | P2: 45778 | Q2: =SUMIFS(J$2:J$1000, F$2:F$1000, ">=" & DATE(YEAR(P2), MONTH(P2), 1), F$2:F$1000, "<=" & EOMONTH(P2, 0)) -> 0
E3: 19 | F3: 46474 | H3: 10000 | I3: 2076.13 | J3: =SUM(H3:I3) -> 12076.13 | K3: =IF(F3<=TODAY(),"Check!","Waiting") -> Waiting | M3: سيتي قيت | N3: 14.26 | P3: 45809 | Q3: =SUMIFS(J$2:J$1000, F$2:F$1000, ">=" & DATE(YEAR(P3), MONTH(P3), 1), F$2:F$1000, "<=" & EOMONTH(P3, 0)) -> 0 | R3: بداية الأستثمار
A4: الملاحظات | E4: 26 | F4: 46735 | H4: 20000 | I4: 6217.56 | J4: =SUM(H4:I4) -> 26217.56 | K4: =IF(F4<=TODAY(),"Check!","Waiting") -> Waiting | M4: بارك ليفينق | N4: 15.5 | P4: 45839 | Q4: =SUMIFS(J$2:J$1000, F$2:F$1000, ">=" & DATE(YEAR(P4), MONTH(P4), 1), F$2:F$1000, "<=" & EOMONTH(P4, 0)) -> 0 | R4: اضف معلومات الاستثمار
P5: 45870 | Q5: =SUMIFS(J$2:J$1000, F$2:F$1000, ">=" & DATE(YEAR(P5), MONTH(P5), 1), F$2:F$1000, "<=" & EOMONTH(P5, 0)) -> 0 | R5: اخصم المبلغ من الكاش
P6: 45901 | Q6: =SUMIFS(J$2:J$1000, F$2:F$1000, ">=" & DATE(YEAR(P6), MONTH(P6), 1), F$2:F$1000, "<=" & EOMONTH(P6, 0)) -> 0 | R6: انسخة كاملة السطر الى ALL
A7: التعثرات 0 | P7: 45931 | Q7: =SUMIFS(J$2:J$1000, F$2:F$1000, ">=" & DATE(YEAR(P7), MONTH(P7), 1), F$2:F$1000, "<=" & EOMONTH(P7, 0)) -> 0 | R7: تحقق من التدفقات
P8: 45962 | Q8: =SUMIFS(J$2:J$1000, F$2:F$1000, ">=" & DATE(YEAR(P8), MONTH(P8), 1), F$2:F$1000, "<=" & EOMONTH(P8, 0)) -> 0
P9: 45992 | Q9: =SUMIFS(J$2:J$1000, F$2:F$1000, ">=" & DATE(YEAR(P9), MONTH(P9), 1), F$2:F$1000, "<=" & EOMONTH(P9, 0)) -> 0
P10: 46023 | Q10: =SUMIFS(J$2:J$1000, F$2:F$1000, ">=" & DATE(YEAR(P10), MONTH(P10), 1), F$2:F$1000, "<=" & EOMONTH(P10, 0)) -> 0 | R10: نهاية الأستثمار
P11: 46054 | Q11: =SUMIFS(J$2:J$1000, F$2:F$1000, ">=" & DATE(YEAR(P11), MONTH(P11), 1), F$2:F$1000, "<=" & EOMONTH(P11, 0)) -> 0 | R11: PAID
P12: 46082 | Q12: =SUMIFS(J$2:J$1000, F$2:F$1000, ">=" & DATE(YEAR(P12), MONTH(P12), 1), F$2:F$1000, "<=" & EOMONTH(P12, 0)) -> 0 | R12: غير مكان تاريخ الاستحقاق الى تاريخ السداد
P13: 46113 | Q13: =SUMIFS(J$2:J$1000, F$2:F$1000, ">=" & DATE(YEAR(P13), MONTH(P13), 1), F$2:F$1000, "<=" & EOMONTH(P13, 0)) -> 0 | R13: غير صافي الربح
P14: 46143 | Q14: =SUMIFS(J$2:J$1000, F$2:F$1000, ">=" & DATE(YEAR(P14), MONTH(P14), 1), F$2:F$1000, "<=" & EOMONTH(P14, 0)) -> 0 | R14: اكتب / EARLY OR LATE OR DEF
P15: 46174 | Q15: =SUMIFS(J$2:J$1000, F$2:F$1000, ">=" & DATE(YEAR(P15), MONTH(P15), 1), F$2:F$1000, "<=" & EOMONTH(P15, 0)) -> 0 | R15: اضف مبلغ الدفعة الى الكاش
P16: 46204 | Q16: =SUMIFS(J$2:J$1000, F$2:F$1000, ">=" & DATE(YEAR(P16), MONTH(P16), 1), F$2:F$1000, "<=" & EOMONTH(P16, 0)) -> 0 | R16: انسخ كامل السطر الى ALL
A17: تم التأكد من جميع الأرقام | P17: 46235 | Q17: =SUMIFS(J$2:J$1000, F$2:F$1000, ">=" & DATE(YEAR(P17), MONTH(P17), 1), F$2:F$1000, "<=" & EOMONTH(P17, 0)) -> 0
P18: 46266 | Q18: =SUMIFS(J$2:J$1000, F$2:F$1000, ">=" & DATE(YEAR(P18), MONTH(P18), 1), F$2:F$1000, "<=" & EOMONTH(P18, 0)) -> 0
A19: 0 | B19: 0 | C19: تصحيح الفواصل | P19: 46296 | Q19: =SUMIFS(J$2:J$1000, F$2:F$1000, ">=" & DATE(YEAR(P19), MONTH(P19), 1), F$2:F$1000, "<=" & EOMONTH(P19, 0)) -> 24086
P20: 46327 | Q20: =SUMIFS(J$2:J$1000, F$2:F$1000, ">=" & DATE(YEAR(P20), MONTH(P20), 1), F$2:F$1000, "<=" & EOMONTH(P20, 0)) -> 0
A21: المأشرات | P21: 46357 | Q21: =SUMIFS(J$2:J$1000, F$2:F$1000, ">=" & DATE(YEAR(P21), MONTH(P21), 1), F$2:F$1000, "<=" & EOMONTH(P21, 0)) -> 0
